Workbook

Sheet Sources
B1: Unread
A2: Intext citation | B2: Title | C2: Author | D2: Where I found it | E2: Link | F2: Abstract | G2: My summary | H2: Key Quotes/ Data (with page numbers) | J2: No. of Pages
E3: https://www.treasury.govt.nz/sites/default/files/2007-11/prg-msd-dnzcrif.pdf | F3: Overview of retirement framework in NZ from 2003
B4: NZCTU Economic Bulletin August | D4: Email (subscribed) | E4: https://union.org.nz/economic-bulletin-august-2025/ | F4: In the feature article we examine Inland Revenue’s draft report on tax options for an ageing population. Unless there are changes to taxation, an ageing population will squeeze the government’s accounts from two sides. On the revenue side, it will mean proportionally fewer working-age people are providing tax revenue to the government. On the expenditure side, it will mean a growing superannuation and healthcare bill. Inland Revenue’s briefing discusses the pros and cons of different tax options that can be used to help address this. We take a close look at three in particular: a comprehensive capital gains tax, an inheritance tax, and increases to the GST rate. | G4: to be provided | J4: 19
C5: Nicholas Bar and Peter Diamond | D5: Andrew Binning (Treasury) - First follow up email | E5: https://doi.org/10.1093/acprof:oso/9780195387728.001.0001 | F5: Mandatory pension systems are a worldwide phenomenon. Many need reform. This book, a summary of a longer book, sets out an extensive but nontechnical explanation of the economics of pension design. The book recognizes the multiple objectives of pension plans: consumption smoothing, insurance, poverty relief, and redistribution. Analysis includes discussion of labor markets, capital markets, risk sharing, and gender and family. This is supplemented by discussion of implementation, and of experiences, both good and bad, in many countries, with particular attention to China and Chile. | G5: Andrew advises key points are covered in the two papers reforming pensions and cover the economics of pensions | J5: >210
B6: Reforming pensions: principles, analytical errors and policy directions | C6: Nicholas Bar and Peter Diamond | D6: Andrew Binning Treasury) - First follow up email | E6: https://eprints.lse.ac.uk/25099/1/Reforming_pensions_(LSERO_version).pdf | J6: 28
B7: The Economics of Pensions | C7: Nicholas Bar and Peter Diamond | D7: Andrew Binning Treasury) - First follow up email | E7: https://eprints.lse.ac.uk/2630/1/economics_of_pensions_final.pdf | J7: 40
B8: Reversing Pension Privatization: Rebuilding public pension systems in Eastern European and Latin American countries (2000-18) | C8: International Labour Office | D8: Andrew Binning Treasury) - First follow up email | E8: https://www.ilo.org/sites/default/files/wcmsp5/groups/public/%40ed_protect/%40soc_sec/documents/publication/wcms_648639.pdf | G8: From Andrew: This document sets out criteria for measuring pension systems, and makes a case against save-as-you-go | J8: 70
B9: Beyond Contributory Pensions Fourteen Experiences with Coverage Expansion in Latin America | C9: World Bank | D9: Andrew Binning Treasury) - First follow up email | E9: https://documents1.worldbank.org/curated/en/436241468045861160/pdf/928720PUB0Box3021039009781464803901.pdf | G9: Andrew recommends the first chapter as it sets out criteria for evaluating pension policy | J9: 46
B10: Rethinking Pension Reform | C10: Centre for Ecnomic Policy Research | D10: Andrew Binning Treasury) - First follow up email | E10: https://cepr.org/system/files/publication-files/219445-rethinking_pension_reform.pdf | G10: Andrew: There is a chapter about how changes of the pension age of eligibility affect the uptake of other social welfare policies, with some references to the relevant literature.
B11: Policy Quarterly | D11: Chris Thompson (Treasury) - In person | E11: https://ojs.victoria.ac.nz/pq/issue/view/1030 | G11: Chris advised that the upcoming August edition of this will be able the pension
B12: Pensions, Savings and Housing: A Life-cycle Framework with Policy Simulations | C12: Creedy, John Gemmell, Norman Scobie, Grant | D12: https://digitalnz.org/nzresearch | E12: https://ir.wgtn.ac.nz/server/api/core/bitstreams/89e7da4d-6e1d-409b-a690-ece4e642386d/content | F12: The objective of the paper is to explore the saving and consumption responses of a representative household to a range of policy interventions such as changes in taxes and pension settings. To achieve this, it develops a two-period life-cycle model. The representative household maximises lifetime utility through its choice of optimal levels of consumption, housing and saving. A key feature of the approach is modelling the consumption of housing services as a separate good in retirement along with the implications for saving. Importantly, the model incorporates a government budget constraint involving a pay-as-you-go universal pension. In addition, the model allows for a compulsory private retirement savings scheme. Particular attention in the simulations is given to the potential impact on household saving rates of a range of policy changes. Typically the effect on saving rates is modest. In most instances, it would take very substantial changes in existing policy settings to induce significant increases in household saving rates. | J12: 46
B13: Aotearoa New Zealand in 2050 | C13: NZIER | D13: Retirement Commision website | E13: https://assets.retirement.govt.nz/public/Uploads/Aotearoa-New-Zealand-in-2050-FINAL-v3.pdf | F13: New Zealand Institute of Economic Research (NZIER) was commissioned by Te Ara Ahunga Ora Retirement Commission to explore what Aotearoa New Zealand might look like in 2050 and how retirement income policies may need to adapt. This report draws on existing projections from NZ Stats and Treasury and, in some cases, extends them to 2050 using simple linear prediction models but does not account for underlying drivers. | J13: 64
B14: Revenue Statistics in Asia and the Pacific 2025: New Zealand | C14: OECD | D14: Found during 403 research | E14: https://www.oecd.org/en/publications/revenue-statistics-in-asia-and-the-pacific-2025-country-notes_30d43f41-en/new-zealand_85481e0c-en.html | F14: These economy-specific summaries are based on the results shown in the 2025 edition of Revenue Statistics in Asia and the Pacific. They include data on the level and structure of tax revenue for each of the economies covered by the report up to 2023 and show how their results compare to those of other economies in the region as well as the average for Asia and the Pacific. The summaries provide a detailed breakdown of tax revenue for 2023 in national currency and as a percentage of GDP, while also highlighting changes from 2022. The summaries are updated yearly and are available on the day of the launch of the Revenue Statistics in Asia and the Pacific report.
B15: Employment Responses to Income Effect Evidence from Pension Reform | C15: Sebastian Becker, Hermann Buslei, Johannes Geyer, Peter Haan | D15: From Robert | E15: https://www.diw.de/documents/publikationen/73/diw_01.c.815476.de/dp1941.pdf | F15: From Robert: (this captures the incentive effect from the 'income', which is not exactly the same as the incentive effect from the means testing itself, but I think we can just gloss over that difference for now, and later if you want to then you can try to find a more precise elasticity for the means testing, but only if you later decide that is what you think is important) | G15: Labour elasticity data point | J15: 23
B16: Distributional Effects of Means Testing Social Security: Income Versus Wealth | C16: Alan Gustman, Thomas Steinmeier & Nahid Tabatabai | D16: National Bureau of Economic Research | E16: https://www.nber.org/papers/w22424 | G16: Looks at income versus asset means testing and individual versus couple means testing | I16: Asset tested means testing effects younger retirees, potentially encouraging them to work longer
B17: Financial security and economic participation indicator | C17: He Oranga Kaumātua | E17: https://www.officeforseniors.govt.nz/assets/documents/our-work/better-later-life/indicators/Initial-indicator-Better-Later-Life-achieving-financial-security-and-economic-participation.pdf | F17: General employment, income, and asset nformaton for older New Zealandeers
E18: https://www.unitedwaycleveland.org/benefits-cliff-challenges-and-solutions/
B19: The Treasury's CBAx Tool | E19: https://www.treasury.govt.nz/information-and-services/public-sector-leadership/investment-management/investment-planning/treasurys-cbax-tool | F19: Tools to complete a wellbeing focused CBA
B20: Wealth in New Zealand | C20: Max Rashbrooke | F20: Max rashbrook wealth in New Zealand gives a good argument for the s maximin social welfare model towards the end that could be included in thesisReasons to suppose equality of Wellbeing might matter (prioritsrianism)? Because wellbeing begets wellbeing, and those with low wellbeing might be less well able to continue to grow their wellbeing over time Relational egalitarianism - we pay to exist in Society.
C21: Sceince Direct | E21: https://www.sciencedirect.com/topics/economics-econometrics-and-finance/social-welfare-function | F21: Multiple articles about SWF
B22: Book Save as you go or pay as you go? : the age old policy debate | C22: Susan St John
B23: Fiscal sustainability in an ageing population : adapting universal provision | C23: Susan St John
B24: Intergenerational impacts : the sustainability of New Zealand superannuation : commissioned report | C24: Susan St John
B25: Private pensions in New Zealand : can they avert the 'crisis'? | C25: Susan St John
B26: The sociocultural framing of public attitudes to sharing the costs of social care for older people in England | E26: https://tewaharoa.victoria.ac.nz/discovery/fulldisplay?docid=cdi_pubmed_primary_35929403&context=PC&vid=64VUW_INST:VUWNUI&lang=en&search_scope=MyInst_and_CI&adaptor=Primo%20Central&tab=all&query=any,contains,%22politic*%22%20AND%20%22comm*%22%20AND%20%22tax%22%20AND%20%22reform%22%20AND%20%22public%22%20AND%20%22narrative%22&offset=0
B27: Relevant
E28: https://www.treasury.govt.nz/sites/default/files/2013-07/twp13-13.pdf | F28: Pensioners earn relatively low market incomes
E29: https://www.treasury.govt.nz/publications/research-and-commentary/rangitaki-blog/why-high-income-households-get-benefits | F29: Equivalisation is a process to make incomes comparable across different sized households. So for instance a $40,000 household with one adult is not considered the same as a $40,000 household with two adults and two children. This is because the household with the children has to share their income across more family members, so the single adult would usually be assumed to be better-off – in material terms – than the family with children (ignoring wealth). The 'equivalised income' takes account of this difference. In this case we use square root equivalisation which is the method used by the OECD, though it should be noted there are different ways you can equivalise incomes. We use these equivalised incomes to order households and create the quintiles.
E30: https://www.health.govt.nz/publications/annual-update-of-key-results-202425-new-zealand-health-survey | F30: Wealth and income have a greater impact on wellbeing than age | G30: Ofcourse age changes - my thesis looks only at a snapshot but year, and people might be willing to take some losses now to enjoy a lack of means testing in retirement
B31: HYEFU 2020 New Zealand Superannuation Fund (NZSF) Track – Contribution Scenarios | E31: https://www.treasury.govt.nz/publications/new-zealand-superannuation-fund-contribution-rate-model-hyefu-2020 | F31: 0.696 billion projected withdrawl from the fund in 2040/2041 financial year | G31: 5.92258798280081 billion withdrawal from the fund in 2059/2060 financial year
B32: Golden Years - Understanding the New Zealand Superannuation Fund | C32: The Treasury Working Paper | E32: https://www.treasury.govt.nz/publications/wp/wp-21-01#some-history-of-the-nzsf | F32: Aim of Super fund to ensure we pay for new zealand superannuation while we can best afford to do it. Original old age pensionfrom 1898 included a test for income, assets, and good character Aging of the population likely to continue for atleast a century | G32: "This means that a one-off rise in the age of eligibility for NZS, say to 66 or 67, will not flatten the aggregate net NZS to GDP projection. That is certainly not stated in order to discourage debate around such a policy option, but rather to simply point out that such a single change will not be sufficient to stop the rise of NZS to GDP" | H32: There is the potential that retirees will continue to be an active part of thee labour force for longer, although the impact of this is expected to be small. | I32: It's not just that NZS is growing, but that GDP growth is slowing/ per capita GDP decreasing? | J32: from 2100 onwards, the aggregate net NZS expense to GDP stabilises at 8.09 percent. - Figure from Treasury Budget 2020
B33: Estimating the Distribution of Wealth in New Zealand | C33: the treasury | E33: https://www.treasury.govt.nz/sites/default/files/2023-04/twp23-01.pdf | F33: We vastly underestimate wealth in the top 10%
E34: https://assets.retirement.govt.nz/public/Uploads/Policy/TAAO-RC-Policy-Paper-What-else-do-people-have-beyond-KS-and-NZS_AW.pdf | F34: Poorest 50% of New Zealanders have neglible retirement wealth Retirement Commission anticipates a significant decrease in home ownership among retirees. The richest will double what they receive from NZS via their own savings The exclusion of the famil home from asset testing benefits Pākeha and wealthier New Zealanders
E35: https://assets.retirement.govt.nz/public/Uploads/Retirement-Income-Policy-Review/2025-RRIP/Review-of-Retirement-Income-Policies-2025_WEB.pdf | F35: Most of the recommendations are around kiwisaver- no real mention of means testing, just encourangement for cross-party commitment to a long term plan as a pre-requisit for making any changes
E36: https://www.aut.ac.nz/__data/assets/pdf_file/0006/654540/Working-paper-22_02.pdf | F36: Wealth inequality follows income inequality becausethe savings rate or the rich stays stable relative to the average savings rate for the whole population
E37: https://data-explorer.oecd.org/vis?tm=labour%20force%20participation%2065%2B&pg=0&snb=3&df[ds]=dsDisseminateFinalDMZ&df[id]=DSD_LFS%40DF_LFS_INDIC&df[ag]=OECD.ELS.SAE&df[vs]=1.1&dq=AUS%2BAUT%2BBEL%2BCAN%2BCHL%2BCOL%2BCRI%2BCZE%2BDNK%2BEST%2BFIN%2BFRA%2BDEU%2BGRC%2BHUN%2BISL%2BIRL%2BISR%2BITA%2BJPN%2BKOR%2BLVA%2BLTU%2BLUX%2BMEX%2BNLD%2BNZL%2BNOR%2BPOL%2BPRT%2BSVK%2BSVN%2BESP%2BSWE%2BCHE%2BTUR%2BGBR%2BUSA%2BG7%2BEU27%2BEU19OECD%2BEU22OECD%2BOECD%2BOECD_REP%2BE%2BARG%2BBRA%2BBGR%2BHRV%2BCYP%2BIND%2BMLT%2BMKD%2BPER%2BROU%2BRUS%2BZAF.LF_RATE.PT_POP_SUB._T.Y_GE65.LF&lom=LASTNPERIODS&lo=5&to[TIME_PERIOD]=false&vw=tb | F37: OECD data on labour force participation 13.6% is the average for countries where this data is collected by the OECD in 2024. New Zealand's labour force participation was 25.4% - nearly double
E38: https://www.econstor.eu/handle/10419/205574 | F38: High labour force participation rate has been linked to high eligibility age
E39: https://www.oecd.org/en/publications/2025/07/oecd-employment-outlook-2025_5345f034/full-report/navigating-the-golden-years-making-the-labour-market-work-for-older-workers_2bc681ed.html | F39: Encouraging older workers to stay in the labour market requires an educated population and job flexibility, among other changes - it is not a case of mere incentives, and facilitation may be a more important measure
E40: https://www.treasury.govt.nz/sites/default/files/2018-12/twp04-22.pdf | F40: Higher replacement rate from the pension disincentivies saving as less saving is required to maintain a pre-retirement quality of life
...

Sheet Parameters
A1: Parameter | B1: FY 24/25 Value | C1: Notes | D1: Sources
A2: WorkingAgePopulation | B2: ='Population Projections'!C2 -> 3465800 | C2: ages 15–64
A3: Population65Plus | B3: ='Population Projections'!B2 -> 902100 | C3: ages 65+
A4: EmploymentRate_WorkingAge | B4: 0.781 | C4: fraction of 15–64 employed | D4: https://infoshare.stats.govt.nz/ViewTable.aspx?pxID=a16e84d4-00a9-41d6-8a4a-8bf771bd2d2d | J4: Labour Force Status for people aged 15 to 64 years (Annual-Mar) | Employment rate | 2025
A5: EmploymentRate_65Plus | B5: 0.249 | C5: fraction of 65+ employed | D5: https://infoshare.stats.govt.nz/SelectVariables.aspx?pxID=a3faf5f4-e39a-4dbb-be8e-f81723992bcb | K5: Table: Labour Force Status by Sex by Age Group (Annual-Mar) | Total Both Sexes | Aged 65 years and over | Employment rate | 2025
A6: Employed 65+ population | B6: =B5*B3 -> 224622.9
A7: NZS_Annual single | B7: 538.42 | C7: net annual NZS per person | D7: https://www.workandincome.govt.nz/map/deskfile/nz-superannuation-and-veterans-pension-tables/new-zealand-superannuation-and-veterans-pension-ra.html
A8: NZS_annual couple | B8: 414.17 | C8: net annual NZS per person (half couple's rate) | D8: https://www.workandincome.govt.nz/map/deskfile/nz-superannuation-and-veterans-pension-tables/new-zealand-superannuation-and-veterans-pension-ra.html
A9: UtilityParam | C9: u = (y^(-0.26) -1)/-0.26 | D9: https://www.sciencedirect.com/science/article/pii/S0047272708000248
A10: Average inflation | B10: 0.026 | C10: average 2005-2025 | D10: https://www.stats.govt.nz/news/annual-inflation-at-2-7-percent-in-june-2025/
A11: Average real wage growth | B11: 0.03688 | C11: average 1999-2023 | D11: https://www.stats.govt.nz/news/income-growth-for-wage-and-salary-earners-remains-strong/
A12: Income multiplier | B12: =(B11-B10) + 1 -> 1.01088
A13: Ratio 65+ pop partnered | B13: 0.58 | D13: https://explore.data.stats.govt.nz/vis?tm=relationship&pg=0&snb=14&df%5bds%5d=ds-nsiws-disseminate&df%5bid%5d=CEN23_POP_008&df%5bag%5d=STATSNZ&df%5bvs%5d=1.0&dq=2013%2B2018%2B2023.9999%2B99999%2B999999.99...99&to%5bTIME%5d=false
A14: Ratio 65+ pop single | B14: 0.42 | D14: https://explore.data.stats.govt.nz/vis?tm=relationship&pg=0&snb=14&df%5bds%5d=ds-nsiws-disseminate&df%5bid%5d=CEN23_POP_008&df%5bag%5d=STATSNZ&df%5bvs%5d=1.0&dq=2013%2B2018%2B2023.9999%2B99999%2B999999.99...99&to%5bTIME%5d=false
A15: Income from wealth | B15: 0.1 | D15: Brave AI overveiw- need to replace
A16: Median home value | B16: 873177 | D16: https://regions.infometrics.co.nz/new-zealand/income-and-housing/house-values
A18: Parameters by Income Decile | B18: Base year total income | C18: Base year average income | D18: Revenue share BAU | E18: Revenue share progressive | F18: Share of employed 65+ population | G18: Weights for share of employed 65+ population
A19: 1 | B19: =798.1*1000000 -> 798100000 | C19: =B19/$A$32 -> 2785.4657 | D19: ='Revenue share calc'!E2 -> 0.0036096394 | E19: ='Revenue share calc'!H2 -> 0 | F19: =G19/55 -> 0.18181818 | G19: 10
A20: 2 | B20: =3618.3*1000000 -> 3618300000 | C20: =B20/$A$32 -> 12628.306 | D20: ='Revenue share calc'!E3 -> 0.014401036 | E20: ='Revenue share calc'!H3 -> 0.0032866726 | F20: =G20/55 -> 0.16363636 | G20: 9
A21: 3 | B21: =7546.1*1000000 -> 7546100000 | C21: =B21/$A$32 -> 26336.804 | D21: ='Revenue share calc'!E4 -> 0.031399077 | E21: ='Revenue share calc'!H4 -> 0.010281718 | F21: =G21/55 -> 0.14545455 | G21: 8
A22: 4 | B22: =11905.5*1000000 -> 11905500000 | C22: =B22/$A$32 -> 41551.638 | D22: ='Revenue share calc'!E5 -> 0.051692243 | E22: ='Revenue share calc'!H5 -> 0.021628655 | F22: =G22/55 -> 0.12727273 | G22: 7
A23: 5 | B23: =15606.1*1000000 -> 15606100000 | C23: =B23/$A$32 -> 54467.181 | D23: ='Revenue share calc'!E6 -> 0.070583126 | E23: ='Revenue share calc'!H6 -> 0.042527271 | F23: =G23/55 -> 0.10909091 | G23: 6
A24: 6 | B24: =18610.5*1000000 -> 18610500000 | C24: =B24/$A$32 -> 64952.901 | D24: ='Revenue share calc'!E7 -> 0.090905111 | E24: ='Revenue share calc'!H7 -> 0.067619181 | F24: =G24/55 -> 0.090909091 | G24: 5
A25: 7 | B25: =21785.7*1000000 -> 21785700000 | C25: =B25/$A$32 -> 76034.734 | D25: ='Revenue share calc'!E8 -> 0.11035602 | E25: ='Revenue share calc'!H8 -> 0.098944896 | F25: =G25/55 -> 0.072727273 | G25: 4
A26: 8 | B26: =25966.5*1000000 -> 25966500000 | C26: =B26/$A$32 -> 90626.232 | D26: ='Revenue share calc'!E9 -> 0.13623162 | E26: ='Revenue share calc'!H9 -> 0.14151958 | F26: =G26/55 -> 0.054545455 | G26: 3
A27: 9 | B27: =32317.2*1000000 -> 32317200000 | C27: =B27/$A$32 -> 112790.95 | D27: ='Revenue share calc'!E10 -> 0.17539672 | E27: ='Revenue share calc'!H10 -> 0.20548666 | F27: =G27/55 -> 0.036363636 | G27: 2
A28: 10 | B28: =56243*1000000 -> 56243000000 | C28: =B28/$A$32 -> 196294.89 | D28: ='Revenue share calc'!E11 -> 0.3154254 | E28: ='Revenue share calc'!H11 -> 0.40870536 | F28: =G28/55 -> 0.018181818 | G28: 1
A29: Source:
A30: https://www.ird.govt.nz/about-us/tax-statistics/revenue-refunds/wage-salary-distributions/wage-and-salary-statistics-datasets
A31: Quintile pop size:
A32: 286523
A34: Parameters by Wealth Quintile | B34: Total Wealth | C34: Adjusted for negative values+ housing value | D34: Income from wealth | E34: Weighting of 65+ population | F34: Share of 65+ population
A35: 1 | B35: -3546560 | C35: 0 | D35: 0 | E35: 1 | F35: =E35/15 -> 0.066666667
A36: 2 | B36: 59384533 | C36: =B36-$B$16 -> 58511356 | D36: =C36*$B$15 -> 5851135.6 | E36: 2 | F36: =E36/15 -> 0.13333333
A37: 3 | B37: 213316981 | C37: =B37-$B$16 -> 212443804 | D37: =C37*$B$15 -> 21244380 | E37: 3 | F37: =E37/15 -> 0.2
A38: 4 | B38: 426978284 | C38: =B38-$B$16 -> 426105107 | D38: =C38*$B$15 -> 42610511 | E38: 4 | F38: =E38/15 -> 0.26666667
A39: 5 | B39: 1371364554 | C39: =B39-$B$16 -> 1370491377 | D39: =C39*$B$15 -> 1.3704914e+08 | E39: 5 | F39: =E39/15 -> 0.33333333

Sheet Population Projections
A1: Year | B1: 65+ | C1: 15-64 | D1: 65+ scaling factor from base year (2025) | E1: working age scaling factor from base year
A2: 2025 | B2: 902100 | C2: 3465800 | D2: 1 | E2: 1
A3: 2026 | B3: 932200 | C3: 3493500 | D3: =B3/B2 -> 1.0333666 | E3: =C3/$C$2 -> 1.0079924
A4: 2040 | B4: 1287900 | C4: 3911000 | D4: =B4/B2 -> 1.4276688 | E4: =C4/$C$2 -> 1.1284552
A5: 2060 | B5: 1776600 | C5: 4303300 | D5: =B5/B2 -> 1.9694047 | E5: =C5/$C$2 -> 1.241647
A6: 2078 | B6: 1776600 | C6: 3465800
A7: https://explore.data.stats.govt.nz/vis?fs[0]=Society%2C1%7CPopulation%20projections%23CAT_POPULATION_PROJECTIONS%23%7CNational%20population%20projections%23CAT_NATIONAL_POPULATION_PROJECTIONS%23&pg=0&fc=Society&bp=true&snb=9&df[ds]=ds-nsiws-disseminate&df[id]=POPPR_NAT_007&df[ag]=STATSNZ&df[vs]=1.0&dq=.2025%2B2040%2B2060%2B2078.SEX3.AGE6500%2BAGE4064%2BAGE1539%2BTOTALALLAGES&ly[rw]=YEAR_POPPR_NAT_007&ly[cl]=SCENARIO_POPPR_NAT_007&to[TIME]=false
A8: Based on Median projections

Sheet Wealth Model
A1: Quintile | B1: Year | D1: NZS income per recipient | O1: Tax BAU | R1: Tax Progressive | U1: Gross income | W1: Net Income BAU | X1: Net income Progressive | Y1: Welfare score BAU | AA1: Welfare score progressive | AC1: SWF BAU CRRA | AG1: SWF Progressive CRRA | AK1: SWF BAU log | AO1: SWF Progressive log
B2: Year | C2: Years since base | D2: Base year annual rate singles | E2: Base year annual rate couples | F2: Mulitplier | G2: Current year real rate singles | H2: Current year annual rate couples | I2: Total 65+ population | J2: Single | K2: In a relationship | L2: NZS paid singles rate | M2: NZS paid couples rate | N2: NZS paid total to 65+ | O2: Revenue share | P2: Required tax rate | Q2: Decile NZS cost | R2: Revenue share | S2: Required tax rate | T2: Decile NZS cost | U2: Wealth income | V2: Pension income | W2: Total income | X2: Total income | Y2: CRRA | Z2: Log | AA2: CRRA | AB2: Log | AC2: Utilitarian | AD2: Adjusted score | AE2: Prioritarian | AF2: Maximin | AG2: Utilitarian | AH2: Adjusted score | AI2: Prioritarian | AJ2: Maximin | AK2: Utilitarian | AL2: Adjusted score | AM2: Prioritarian | AN2: Maximin | AO2: Utilitarian | AP2: Adjusted score | AQ2: Prioritarian | AR2: Maximin
A3: Overall | B3: 2026 | C3: 1 | D3: =Parameters!$B$7 -> 538.42 | E3: =Parameters!$B$8 -> 414.17 | F3: =Parameters!$B$12 -> 1.01088 | G3: =D3*POWER(F3,C3) -> 544.27801 | H3: =E3*POWER(F3,C3) -> 418.67617 | I3: =Parameters!B3*'Population Projections'!D3 -> 932200 | J3: =I3*Parameters!$B$14 -> 391524 | K3: =I3*Parameters!$B$13 -> 540676 | L3: =J3*G3 -> 2.130979e+08 | M3: =K3*H3 -> 2.2636816e+08 | N3: =M3+L3 -> 4.3946606e+08 | T3: =SUM(T4:T13) -> 4.3946606e+08 | U3: =SUM(U4:U8) -> 2.0900466e+08 | V3: =SUM(V4:V8) -> 4.3946606e+08 | W3: =U3+V3-Q3 -> 6.4847072e+08 | X3: =U3+V3-T3 -> 2.0900466e+08 | Y3: =Parameters!C9 -> u = (y^(-0.26) -1)/-0.26 | AC3: =SUM(Y4:Y13) -> 15.233206 | AE3: =SUM(_xlfn.ANCHORARRAY(AD4)) -> 7.8059472 | AF3: =MIN(Y4:Y13) -> 3.8021339 | AG3: =SUM(AA4:AA13) -> 15.237387 | AI3: =SUM(AH4:AH13) -> 7.8070178 | AJ3: =MIN(AA4:AA13) -> 3.8021339 | AK3: =SUM(Z4:Z7) -> 30.906298 | AM3: =SUM(AL4:AL7) -> 11.118106 | AN3: =MIN(Z4:Z7) -> 7.4668341 | AO3: =SUM(AB4:AB7) -> 31.106545 | AQ3: =SUM(AP4:AP7) -> 11.118106 | AR3: =MIN(AB4:AB7) -> 7.4668341
A4: 1 | O4: ='Revenue share calc'!E18 -> 0 | P4: 0 | Q4: =$N$3*O4 -> 0 | R4: ='Revenue share calc'!H18 -> 0 | T4: =$N$3*R4 -> 0 | U4: =Parameters!D35*Parameters!$B$12 -> 0 | V4: =$N$3*Parameters!F35 -> 29297737 | W4: =U4+V4-Q4 -> 29297737 | X4: =U4+V4-T4 -> 29297737 | Y4: =(POWER(W4, -0.26) - 1)/-0.26 -> 3.8021339 | Z4: =LOG(W4) -> 7.4668341 | AA4: =(POWER(X4, -0.26) - 1)/-0.26 -> 3.8021339 | AB4: =LOG(X4) -> 7.4668341 | AD4: {=SQRT(Y4:Y7)} -> 1.9499061 | AH4: {=SQRT(AA4:AA7)} -> 1.9499061 | AL4: =SQRT(Z4) -> 2.7325508 | AP4: =SQRT(Z4) -> 2.7325508
A5: 2 | O5: ='Revenue share calc'!E19 -> 0.022599597 | P5: =(O5*$N$3)/Parameters!D36 -> 1.6974066 | Q5: =P5*Parameters!D36 -> 9931756 | R5: ='Revenue share calc'!H19 -> 0.0076027075 | S5: =(R5*$N$3)/Parameters!D36 -> 0.57102281 | T5: =S5*Parameters!D36 -> 3341131.9 | U5: =Parameters!D36*Parameters!$B$12 -> 5914796 | V5: =$N$3*Parameters!F36 -> 58595475 | W5: =U5+V5-Q5 -> 54578515 | X5: =U5+V5-T5 -> 61169139 | Y5: =(POWER(W5, -0.26) - 1)/-0.26 -> 3.8087082 | Z5: =LOG(W5) -> 7.7370217 | AA5: =(POWER(X5, -0.26) - 1)/-0.26 -> 3.8098019 | AB5: =LOG(X5) -> 7.7865324 | AD5: 1.9515912 | AH5: 1.9518714 | AL5: =SQRT(Z5) -> 2.7815502 | AP5: =SQRT(Z5) -> 2.7815502
A6: 3 | O6: ='Revenue share calc'!E20 -> 0.090784163 | P6: =(O6*$N$3)/Parameters!D37 -> 1.8779817 | Q6: =P6*Parameters!D37 -> 39896558 | R6: ='Revenue share calc'!H20 -> 0.055208021 | S6: =(R6*$N$3)/Parameters!D37 -> 1.1420456 | T6: =S6*Parameters!D37 -> 24262052 | U6: =Parameters!D37*Parameters!$B$12 -> 21475519 | V6: =$N$3*Parameters!F37 -> 87893212 | W6: =U6+V6-Q6 -> 69472173 | X6: =U6+V6-T6 -> 85106680 | Y6: =(POWER(W6, -0.26) - 1)/-0.26 -> 3.8109852 | Z6: =LOG(W6) -> 7.8418109 | AA6: =(POWER(X6, -0.26) - 1)/-0.26 -> 3.8127931 | AB6: =LOG(X6) -> 7.9299636 | AD6: 1.9521745 | AH6: 1.9526375 | AL6: =SQRT(Z6) -> 2.8003234 | AP6: =SQRT(Z6) -> 2.8003234
A7: 4 | O7: ='Revenue share calc'!E21 -> 0.19959712 | P7: =(O7*$N$3)/Parameters!D38 -> 2.0585569 | Q7: =P7*Parameters!D38 -> 87716161 | R7: ='Revenue share calc'!H21 -> 0.17400811 | S7: =(R7*$N$3)/Parameters!D38 -> 1.7946431 | T7: =S7*Parameters!D38 -> 76470660 | U7: =Parameters!D38*Parameters!$B$12 -> 43074113 | V7: =$N$3*Parameters!F38 -> 1.1719095e+08 | W7: =U7+V7-Q7 -> 72548902 | X7: =U7+V7-T7 -> 83794403 | Y7: =(POWER(W7, -0.26) - 1)/-0.26 -> 3.8113792 | Z7: =LOG(W7) -> 7.8606308 | AA7: =(POWER(X7, -0.26) - 1)/-0.26 -> 3.812658 | AB7: =LOG(X7) -> 7.923215 | AD7: 1.9522754 | AH7: 1.9526029 | AL7: =SQRT(Z7) -> 2.8036817 | AP7: =SQRT(Z7) -> 2.8036817
A8: 5 | O8: ='Revenue share calc'!E22 -> 0.68701912 | P8: =(O8*$N$3)/Parameters!D39 -> 2.203017 | Q8: =P8*Parameters!D39 -> 3.0192158e+08 | R8: ='Revenue share calc'!H22 -> 0.76318116 | S8: =(R8*$N$3)/Parameters!D39 -> 2.4472406 | T8: =S8*Parameters!D39 -> 3.3539222e+08 | U8: =Parameters!D39*Parameters!$B$12 -> 1.3854023e+08 | V8: =$N$3*Parameters!F39 -> 1.4648869e+08 | W8: =U8+V8-Q8 -> -16892666 | X8: =U8+V8-T8 -> -50363298
A10: Used 2024 wealth figures, but kept base year a 2025 to increase comparability with income model
A12: Simple means test - top 2 quintiles no NZS
A13: Quintile | B13: Year | D13: NZS income per recipient | O13: Tax BAU | R13: Tax Progressive | U13: Gross income | W13: Net Income BAU | X13: Net income Progressive | Y13: Welfare score BAU | AA13: Welfare score progressive | AC13: SWF BAU CRRA | AG13: SWF Progressive CRRA | AK13: SWF BAU log | AO13: SWF Progressive log
B14: Year | C14: Years since base | D14: Base year annual rate singles | E14: Base year annual rate couples | F14: Mulitplier | G14: Current year real rate singles | H14: Current year annual rate couples | I14: Total 65+ population | J14: Single | K14: In a relationship | L14: NZS paid singles rate | M14: NZS paid couples rate | N14: NZS paid total to 65+ | O14: Revenue share | P14: Required tax rate | Q14: Decile NZS cost | R14: Revenue share | S14: Required tax rate | T14: Decile NZS cost | U14: Wealth income | V14: Pension income after means test | W14: Total income | X14: Total income | Y14: CRRA | Z14: Log | AA14: CRRA | AB14: Log | AC14: Utilitarian | AD14: Adjusted score | AE14: Prioritarian | AF14: Maximin | AG14: Utilitarian | AH14: Adjusted score | AI14: Prioritarian | AJ14: Maximin | AK14: Utilitarian | AL14: Adjusted score | AM14: Prioritarian | AN14: Maximin | AO14: Utilitarian | AP14: Adjusted score | AQ14: Prioritarian | AR14: Maximin
A15: Overall | B15: 2026 | C15: 1 | D15: =Parameters!$B$7 -> 538.42 | E15: =Parameters!$B$8 -> 414.17 | F15: =Parameters!$B$12 -> 1.01088 | G15: =D15*POWER(F15,C15) -> 544.27801 | H15: =E15*POWER(F15,C15) -> 418.67617 | I15: ='Population Projections'!B3 -> 932200 | J15: =I15*Parameters!$B$14 -> 391524 | K15: =I15*Parameters!$B$13 -> 540676 | L15: =J15*G15 -> 2.130979e+08 | M15: =K15*H15 -> 2.2636816e+08 | N15: =M15+L15 -> 4.3946606e+08 | T15: =SUM(T16:T25) -> 1.7578642e+08 | U15: =SUM(U16:U20) -> 2.0900466e+08 | V15: =SUM(V16:V18) -> 1.7578642e+08 | W15: =U15+V15-Q15 -> 3.8479108e+08 | X15: =U15+V15-T15 -> 2.0900466e+08 | AC15: =SUM(Y16:Y25) -> 19.00589 | AE15: =SUM(AD16:AD20) -> 9.748296 | AF15: =MIN(Y16:Y25) -> 3.7844379 | AG15: =SUM(AA16:AA20) -> 18.991596 | AI15: =SUM(AH16:AH20) -> 9.7446209 | AJ15: =MIN(AA16:AA25) -> 3.774017 | AK15: =SUM(Z16:Z20) -> 37.371398 | AM15: =SUM(AL16:AL20) -> 13.665145 | AN15: =MIN(Z16:Z20) -> 6.902419 | AO15: =SUM(AB16:AB20) -> 37.004133 | AQ15: =SUM(AP16:AP20) -> 13.665145 | AR15: =MIN(AB16:AB20) -> 6.6418057
A16: 1 | N16: =Parameters!F35*$N$15 -> 29297737 | O16: ='Revenue share calc'!E18 -> 0 | Q16: =O16*SUM($N$16:$N$18) -> 0 | R16: ='Revenue share calc'!H18 -> 0 | T16: =R16*SUM($N$16:$N$18) -> 0 | U16: =Parameters!D35*Parameters!$B$12 -> 0 | V16: =N16 -> 29297737 | W16: =U16+V16-Q16 -> 29297737 | X16: =U16+V16-T16 -> 29297737 | Y16: =(POWER(W16, -0.26) - 1)/-0.26 -> 3.8021339 | Z16: =LOG(W16) -> 7.4668341 | AA16: =(POWER(X16, -0.26) - 1)/-0.26 -> 3.8021339 | AB16: =LOG(X16) -> 7.4668341 | AD16: =SQRT(Y16) -> 1.9499061 | AH16: =SQRT(AA16) -> 1.9499061 | AL16: =SQRT(Z16) -> 2.7325508 | AP16: =SQRT(Z16) -> 2.7325508
A17: 2 | N17: =Parameters!F36*$N$15 -> 58595475 | O17: ='Revenue share calc'!E19 -> 0.022599597 | Q17: =O17*SUM($N$16:$N$18) -> 3972702.4 | R17: ='Revenue share calc'!H19 -> 0.0076027075 | T17: =R17*SUM($N$16:$N$18) -> 1336452.8 | U17: =Parameters!D36*Parameters!$B$12 -> 5914796 | V17: =N17 -> 58595475 | W17: =U17+V17-Q17 -> 60537568 | X17: =U17+V17-T17 -> 63173818 | Y17: =(POWER(W17, -0.26) - 1)/-0.26 -> 3.8097036 | Z17: =LOG(W17) -> 7.782025 | AA17: =(POWER(X17, -0.26) - 1)/-0.26 -> 3.8101054 | AB17: =LOG(X17) -> 7.8005371 | AD17: =SQRT(Y17) -> 1.9518462 | AH17: =SQRT(AA17) -> 1.9519491 | AL17: =SQRT(Z17) -> 2.7896281 | AP17: =SQRT(Z17) -> 2.7896281
A18: 3 | N18: =Parameters!F37*$N$15 -> 87893212 | O18: ='Revenue share calc'!E20 -> 0.090784163 | Q18: =O18*SUM($N$16:$N$18) -> 15958623 | R18: ='Revenue share calc'!H20 -> 0.055208021 | T18: =R18*SUM($N$16:$N$18) -> 9704820.7 | U18: =Parameters!D37*Parameters!$B$12 -> 21475519 | V18: =N18 -> 87893212 | W18: =U18+V18-Q18 -> 93410108 | X18: =U18+V18-T18 -> 99663911 | Y18: =(POWER(W18, -0.26) - 1)/-0.26 -> 3.8135909 | Z18: =LOG(W18) -> 7.9703939 | AA18: =(POWER(X18, -0.26) - 1)/-0.26 -> 3.8141349 | AB18: =LOG(X18) -> 7.9985379 | AD18: =SQRT(Y18) -> 1.9528417 | AH18: =SQRT(AA18) -> 1.952981 | AL18: =SQRT(Z18) -> 2.8231886 | AP18: =SQRT(Z18) -> 2.8231886
A19: 4 | N19: =Parameters!F38*$N$15 -> 1.1719095e+08 | O19: ='Revenue share calc'!E21 -> 0.19959712 | Q19: =O19*SUM($N$16:$N$18) -> 35086464 | R19: ='Revenue share calc'!H21 -> 0.17400811 | T19: =R19*SUM($N$16:$N$18) -> 30588264 | U19: =Parameters!D38*Parameters!$B$12 -> 43074113 | V19: 0 | W19: =U19+V19-Q19 -> 7987648.7 | X19: =U19+V19-T19 -> 12485849 | Y19: =(POWER(W19, -0.26) - 1)/-0.26 -> 3.7844379 | Z19: =LOG(W19) -> 6.902419 | AA19: =(POWER(X19, -0.26) - 1)/-0.26 -> 3.7912051 | AB19: =LOG(X19) -> 7.0964181 | AD19: =SQRT(Y19) -> 1.9453632 | AH19: =SQRT(AA19) -> 1.9471017 | AL19: =SQRT(Z19) -> 2.6272455 | AP19: =SQRT(Z19) -> 2.6272455
A20: 5 | N20: =Parameters!F39*$N$15 -> 1.4648869e+08 | O20: ='Revenue share calc'!E22 -> 0.68701912 | Q20: =O20*SUM($N$16:$N$18) -> 1.2076863e+08 | R20: ='Revenue share calc'!H22 -> 0.76318116 | T20: =R20*SUM($N$16:$N$18) -> 1.3415689e+08 | U20: =Parameters!D39*Parameters!$B$12 -> 1.3854023e+08 | V20: 0 | W20: =U20+V20-Q20 -> 17771598 | X20: =U20+V20-T20 -> 4383345.7 | Y20: =(POWER(W20, -0.26) - 1)/-0.26 -> 3.7960238 | Z20: =LOG(W20) -> 7.2497265 | AA20: =(POWER(X20, -0.26) - 1)/-0.26 -> 3.774017 | AB20: =LOG(X20) -> 6.6418057 | AD20: =SQRT(Y20) -> 1.9483387 | AH20: =SQRT(AA20) -> 1.9426829 | AL20: =SQRT(Z20) -> 2.6925316 | AP20: =SQRT(Z20) -> 2.6925316

Sheet Wealth by age
A1: 461053726
A2: 302831605
A4: =A1+A2 -> 763885331 | B4: total net worth of individuals 65+
A5: 2067497792 | B5: total net work of individual all ages
A7: =A4/A5 -> 0.36947335 | B7: 65+ age group holds 37% of the wealth

Sheet Income Model
A1: Decile | B1: Year | D1: NZS income per recipient | U1: Tax BAU | X1: Tax Progressive | AA1: Size tax paying group by income group | AC1: Gross income | AE1: Net Income BAU | AF1: Net income Progressive | AG1: Quintile size | AH1: Average income pp BAU | AI1: Average income pp progressive | AJ1: Welfare score BAU | AM1: Welfare score progressive | AP1: SWF BAU utility CRRA | AT1: SWF BAU utility log | AX1: SWF Progressive utility CRRA | BB1: SWF Progressive utility CRRA
B2: Year | C2: Years since base | D2: Base year annual rate singles | E2: Base year annual rate couples | F2: Mulitplier | G2: Current year real rate singles | H2: Current year annual rate couples | I2: 65+ employed population current year | J2: Single | K2: In a relationship | L2: NZS paid singles rate | M2: NZS paid couples rate | N2: NZS paid total to employed 65+ | O2: Total 65+ population | P2: Single | Q2: In a relationship | R2: NZS paid singles rate | S2: NZS paid couples rate | T2: NZS paid total to 65+ | U2: Revenue share | V2: Implied average tax rate | W2: Decile NZS cost | X2: Revenue share | Y2: Implied average tax rate | Z2: Decile NZS cost | AA2: Employed working age pop current year | AB2: Total tax paying population | AC2: Employment income | AD2: Pension income | AE2: Total income | AF2: Total income | AJ2: CRRA | AK2: BAU Welfare Normalised | AL2: BAU alternate utility | AM2: CRRA | AN2: Progressive Welfare Normalised | AO2: Progressive alternate utility | AP2: Utilitarian | AQ2: Adjusted score | AR2: Prioritarian | AS2: Maximin | AT2: Utilitarian | AU2: Adjusted score | AV2: Prioritarian | AW2: Maximin | AX2: Utilitarian | AY2: Adjusted score | AZ2: Prioritarian | BA2: Maximin | BB2: Utilitarian | BC2: Adjusted score | BD2: Prioritarian | BE2: Maximin
A3: Overall | B3: 2026 | C3: 1 | D3: =Parameters!$B$7 -> 538.42 | E3: =Parameters!$B$8 -> 414.17 | F3: =Parameters!$B$12 -> 1.01088 | G3: =D3*POWER(F3,C3) -> 544.27801 | H3: =E3*POWER(F3,C3) -> 418.67617 | I3: =Parameters!B5*'Population Projections'!B3 -> 232117.8 | J3: =I3*Parameters!$B$14 -> 97489.476 | K3: =I3*Parameters!$B$13 -> 134628.32 | L3: =J3*G3 -> 53061378 | M3: =K3*H3 -> 56365671 | N3: =M3+L3 -> 1.0942705e+08 | O3: ='Population Projections'!B3 -> 932200 | P3: =O3*Parameters!$B$14 -> 391524 | Q3: =O3*Parameters!$B$13 -> 540676 | R3: =P3*G3 -> 2.130979e+08 | S3: =Q3*H3 -> 2.2636816e+08 | T3: =S3+R3 -> 4.3946606e+08 | Z3: =SUM(Z4:Z13) -> 4.3946606e+08 | AA3: ='Population Projections'!C3*Parameters!B4 -> 2728423.5 | AB3: =AA3+I3 -> 2960541.3 | AC3: =SUM(AC4:AC13) -> 196512039360 | AD3: =N3 -> 1.0942705e+08 | AE3: =AC3+AD3-W3 -> 1.9662147e+11 | AF3: =AC3+AD3-Z3 -> 1.96182e+11 | AJ3: =Parameters!C9 -> u = (y^(-0.26) -1)/-0.26 | AP3: =SUM(AK4:AK13) -> 241.29986 | AR3: =SUM(_xlfn.ANCHORARRAY(AQ4)) -> 46.377889 | AS3: =MIN(AJ4:AJ13) -> 3.350943 | AT3: =SUM(AL4:AL13) -> 46.294556 | AV3: =SUM(AU4:AU13) -> 21.479741 | AW3: =MIN(AL4:AL13) -> 3.4239865 | AX3: =SUM(AN4:AN13) -> 241.10809 | AZ3: =SUM(AY4:AY13) -> 46.359499 | BA3: =MIN(AM4:AM13) -> 3.3511902 | BB3: =SUM(AO4:AO13) -> 46.297119 | BD3: =SUM(BC3:BC13) -> 21.480385 | BE3: =MIN(AO4:AO13) -> 3.4248207
A4: 1 | U4: =Parameters!D19 -> 0.0036096394 | W4: =$T$3*U4 -> 1586314 | X4: {=Parameters!E19:E28} -> 0 | Y4: =(X4*$T$3)/(Parameters!B19*Parameters!$B$12) -> 0 | Z4: =$T$3*X4 -> 0 | AC4: =Parameters!B19*Parameters!$B$12 -> 806783328 | AD4: =$AD$3*Parameters!F19 -> 19895827 | AE4: =AC4+AD4-W4 -> 8.2509284e+08 | AF4: =AC4+AD4-Z4 -> 8.2667916e+08 | AG4: =($AA$3/10)+(Parameters!F20*$I$3) -> 310825.26 | AH4: =AE4/AG4 -> 2654.5231 | AI4: =AF4/AG4 -> 2659.6267 | AJ4: =(POWER(AH4, -0.26) - 1)/-0.26 -> 3.350943 | AK4: =(AJ4-$AJ$4)*100 -> 0 | AL4: =LOG(AH4) -> 3.4239865 | AM4: =(POWER(AI4, -0.26) - 1)/-0.26 -> 3.3511902 | AN4: =(AM4-$AM$4)*100 -> 0 | AO4: =LOG(AI4) -> 3.4248207 | AQ4: {=SQRT(AK4:AK13)} -> 0 | AU4: =SQRT(AL4) -> 1.8504017 | AY4: {=SQRT(AN4:AN13)} -> 0 | BC4: =SQRT(AO4) -> 1.8506271
A5: 2 | U5: =Parameters!D20 -> 0.014401036 | V5: =(U5*$T$3)/(Parameters!B19*Parameters!$B$12) -> 0.0078444441 | W5: =$T$3*U5 -> 6328766.7 | X5: 0.0032866726 | Y5: =(X5*$T$3)/(Parameters!B20*Parameters!$B$12) -> 0.00039489134 | Z5: =$T$3*X5 -> 1444381.1 | AC5: =Parameters!B20*Parameters!$B$12 -> 3657667104 | AD5: =$AD$3*Parameters!F20 -> 17906244 | AE5: =AC5+AD5-W5 -> 3.6692446e+09 | AF5: =AC5+AD5-Z5 -> 3.674129e+09 | AG5: =($AA$3/10)+(Parameters!F21*$I$3) -> 306604.94 | AH5: =AE5/AG5 -> 11967.337 | AI5: =AF5/AG5 -> 11983.267 | AJ5: =(POWER(AH5, -0.26) - 1)/-0.26 -> 3.5113833 | AK5: =(AJ5-$AJ$4)*100 -> 16.044027 | AL5: =LOG(AH5) -> 4.0779975 | AM5: =(POWER(AI5, -0.26) - 1)/-0.26 -> 3.511499 | AN5: =(AM5-$AM$4)*100 -> 16.030879 | AO5: =LOG(AI5) -> 4.0785752 | AQ5: 4.0054996 | AU5: =SQRT(AL5) -> 2.0194052 | AY5: 4.0038581 | BC5: =SQRT(AO5) -> 2.0195483
A6: 3 | U6: =Parameters!D21 -> 0.031399077 | V6: =(U6*$T$3)/(Parameters!B20*Parameters!$B$12) -> 0.0037725765 | W6: =$T$3*U6 -> 13798829 | X6: 0.010281718 | Y6: =(X6*$T$3)/(Parameters!B21*Parameters!$B$12) -> 0.00059233701 | Z6: =$T$3*X6 -> 4518466.1 | AC6: =Parameters!B21*Parameters!$B$12 -> 7628201568 | AD6: =$AD$3*Parameters!F21 -> 15916662 | AE6: =AC6+AD6-W6 -> 7.6303194e+09 | AF6: =AC6+AD6-Z6 -> 7.6395998e+09 | AG6: =($AA$3/10)+(Parameters!F22*$I$3) -> 302384.62 | AH6: =AE6/AG6 -> 25233.821 | AI6: =AF6/AG6 -> 25264.512 | AJ6: =(POWER(AH6, -0.26) - 1)/-0.26 -> 3.5704067 | AK6: =(AJ6-$AJ$4)*100 -> 21.946369 | AL6: =LOG(AH6) -> 4.401983 | AM6: =(POWER(AI6, -0.26) - 1)/-0.26 -> 3.5704938 | AN6: =(AM6-$AM$4)*100 -> 21.930358 | AO6: =LOG(AI6) -> 4.4025109 | AQ6: 4.6846952 | AU6: =SQRT(AL6) -> 2.0980903 | AY6: 4.682986 | BC6: =SQRT(AO6) -> 2.0982161
A7: 4 | U7: =Parameters!D22 -> 0.051692243 | V7: =(U7*$T$3)/(Parameters!B21*Parameters!$B$12) -> 0.0029780265 | W7: =$T$3*U7 -> 22716986 | X7: 0.021628655 | Y7: =(X7*$T$3)/(Parameters!B22*Parameters!$B$12) -> 0.00078978268 | Z7: =$T$3*X7 -> 9505059.7 | AC7: =Parameters!B22*Parameters!$B$12 -> 12035031840 | AD7: =$AD$3*Parameters!F22 -> 13927079 | AE7: =AC7+AD7-W7 -> 1.2026242e+10 | AF7: =AC7+AD7-Z7 -> 1.2039454e+10 | AG7: =($AA$3/10)+(Parameters!F23*$I$3) -> 298164.29 | AH7: =AE7/AG7 -> 40334.28 | AI7: =AF7/AG7 -> 40378.591 | AJ7: =(POWER(AH7, -0.26) - 1)/-0.26 -> 3.6020631 | AK7: =(AJ7-$AJ$4)*100 -> 25.11201 | AL7: =LOG(AH7) -> 4.6056743 | AM7: =(POWER(AI7, -0.26) - 1)/-0.26 -> 3.6021328 | AN7: =(AM7-$AM$4)*100 -> 25.094253 | AO7: =LOG(AI7) -> 4.6061512 | AQ7: 5.0111885 | AU7: =SQRT(AL7) -> 2.1460835 | AY7: 5.0094165 | BC7: =SQRT(AO7) -> 2.1461946
A8: 5 | U8: =Parameters!D23 -> 0.070583126 | V8: =(U8*$T$3)/(Parameters!B22*Parameters!$B$12) -> 0.0025773832 | W8: =$T$3*U8 -> 31018888 | X8: 0.042527271 | Y8: =(X8*$T$3)/(Parameters!B23*Parameters!$B$12) -> 0.001184674 | Z8: =$T$3*X8 -> 18689292 | AC8: =Parameters!B23*Parameters!$B$12 -> 15775894368 | AD8: =$AD$3*Parameters!F23 -> 11937496 | AE8: =AC8+AD8-W8 -> 1.5756813e+10 | AF8: =AC8+AD8-Z8 -> 1.5769143e+10 | AG8: =($AA$3/10)+(Parameters!F24*$I$3) -> 293943.97 | AH8: =AE8/AG8 -> 53604.818 | AI8: =AF8/AG8 -> 53646.764 | AJ8: =(POWER(AH8, -0.26) - 1)/-0.26 -> 3.6194632 | AK8: =(AJ8-$AJ$4)*100 -> 26.852018 | AL8: =LOG(AH8) -> 4.7292038 | AM8: =(POWER(AI8, -0.26) - 1)/-0.26 -> 3.6195093 | AN8: =(AM8-$AM$4)*100 -> 26.831904 | AO8: =LOG(AI8) -> 4.7295435 | AQ8: 5.1818933 | AU8: =SQRT(AL8) -> 2.1746733 | AY8: 5.1799521 | BC8: =SQRT(AO8) -> 2.1747514
A9: 6 | U9: =Parameters!D24 -> 0.090905111 | V9: =(U9*$T$3)/(Parameters!B23*Parameters!$B$12) -> 0.0025323262 | W9: =$T$3*U9 -> 39949711 | X9: 0.067619181 | Y9: =(X9*$T$3)/(Parameters!B24*Parameters!$B$12) -> 0.0015795654 | Z9: =$T$3*X9 -> 29716335 | AC9: =Parameters!B24*Parameters!$B$12 -> 18812982240 | AD9: =$AD$3*Parameters!F24 -> 9947913.5 | AE9: =AC9+AD9-W9 -> 1.878298e+10 | AF9: =AC9+AD9-Z9 -> 1.8793214e+10 | AG9: =($AA$3/10)+(Parameters!F25*$I$3) -> 289723.64 | AH9: =AE9/AG9 -> 64830.678 | AI9: =AF9/AG9 -> 64866 | AJ9: =(POWER(AH9, -0.26) - 1)/-0.26 -> 3.6303974 | AK9: =(AJ9-$AJ$4)*100 -> 27.945445 | AL9: =LOG(AH9) -> 4.8117806 | AM9: =(POWER(AI9, -0.26) - 1)/-0.26 -> 3.630428 | AN9: =(AM9-$AM$4)*100 -> 27.923776 | AO9: =LOG(AI9) -> 4.8120171 | AQ9: 5.2863452 | AU9: =SQRT(AL9) -> 2.1935771 | AY9: 5.2842952 | BC9: =SQRT(AO9) -> 2.193631
A10: 7 | U10: =Parameters!D25 -> 0.11035602 | V10: =(U10*$T$3)/(Parameters!B24*Parameters!$B$12) -> 0.0025778862 | W10: =$T$3*U10 -> 48497727 | X10: 0.098944896 | Y10: =(X10*$T$3)/(Parameters!B25*Parameters!$B$12) -> 0.0019744567 | Z10: =$T$3*X10 -> 43482923 | AC10: =Parameters!B25*Parameters!$B$12 -> 22022728416 | AD10: =$AD$3*Parameters!F25 -> 7958330.8 | AE10: =AC10+AD10-W10 -> 2.1982189e+10 | AF10: =AC10+AD10-Z10 -> 2.1987204e+10 | AG10: =($AA$3/10)+(Parameters!F26*$I$3) -> 285503.32 | AH10: =AE10/AG10 -> 76994.513 | AI10: =AF10/AG10 -> 77012.077 | AJ10: =(POWER(AH10, -0.26) - 1)/-0.26 -> 3.6398311 | AK10: =(AJ10-$AJ$4)*100 -> 28.888811 | AL10: =LOG(AH10) -> 4.8864598 | AM10: =(POWER(AI10, -0.26) - 1)/-0.26 -> 3.6398433 | AN10: =(AM10-$AM$4)*100 -> 28.865311 | AO10: =LOG(AI10) -> 4.8865588 | AQ10: 5.3748313 | AU10: =SQRT(AL10) -> 2.2105338 | AY10: 5.3726447 | BC10: =SQRT(AO10) -> 2.2105562
A11: 8 | U11: =Parameters!D26 -> 0.13623162 | V11: =(U11*$T$3)/(Parameters!B25*Parameters!$B$12) -> 0.0027185175 | W11: =$T$3*U11 -> 59869172 | X11: 0.14151958 | Y11: =(X11*$T$3)/(Parameters!B26*Parameters!$B$12) -> 0.002369348 | Z11: =$T$3*X11 -> 62193053 | AC11: =Parameters!B26*Parameters!$B$12 -> 26249015520 | AD11: =$AD$3*Parameters!F26 -> 5968748.1 | AE11: =AC11+AD11-W11 -> 2.6195115e+10 | AF11: =AC11+AD11-Z11 -> 2.6192791e+10 | AG11: =($AA$3/10)+(Parameters!F27*$I$3) -> 281283 | AH11: =AE11/AG11 -> 93127.261 | AI11: =AF11/AG11 -> 93118.999 | AJ11: =(POWER(AH11, -0.26) - 1)/-0.26 -> 3.6497877 | AK11: =(AJ11-$AJ$4)*100 -> 29.884469 | AL11: =LOG(AH11) -> 4.9690768 | AM11: =(POWER(AI11, -0.26) - 1)/-0.26 -> 3.6497831 | AN11: =(AM11-$AM$4)*100 -> 29.859291 | AO11: =LOG(AI11) -> 4.9690383 | AQ11: 5.4666689 | AU11: =SQRT(AL11) -> 2.2291426 | AY11: 5.4643656 | BC11: =SQRT(AO11) -> 2.229134
A12: 9 | U12: =Parameters!D27 -> 0.17539672 | V12: =(U12*$T$3)/(Parameters!B26*Parameters!$B$12) -> 0.0029365256 | W12: =$T$3*U12 -> 77080907 | X12: 0.20548666 | Y12: =(X12*$T$3)/(Parameters!B27*Parameters!$B$12) -> 0.0027642394 | Z12: =$T$3*X12 -> 90304414 | AC12: =Parameters!B27*Parameters!$B$12 -> 32668811136 | AD12: =$AD$3*Parameters!F27 -> 3979165.4 | AE12: =AC12+AD12-W12 -> 3.2595709e+10 | AF12: =AC12+AD12-Z12 -> 3.2582486e+10 | AG12: =($AA$3/10)+(Parameters!F28*$I$3) -> 277062.67 | AH12: =AE12/AG12 -> 117647.42 | AI12: =AF12/AG12 -> 117599.69 | AJ12: =(POWER(AH12, -0.26) - 1)/-0.26 -> 3.6613652 | AK12: =(AJ12-$AJ$4)*100 -> 31.042224 | AL12: =LOG(AH12) -> 5.0705824 | AM12: =(POWER(AI12, -0.26) - 1)/-0.26 -> 3.6613457 | AN12: =(AM12-$AM$4)*100 -> 31.01555 | AO12: =LOG(AI12) -> 5.0704062 | AQ12: 5.5715549 | AU12: =SQRT(AL12) -> 2.2517954 | AY12: 5.5691606 | BC12: =SQRT(AO12) -> 2.2517562
A13: 10 | U13: =Parameters!D28 -> 0.3154254 | V13: =(U13*$T$3)/(Parameters!B27*Parameters!$B$12) -> 0.0042431529 | W13: =$T$3*U13 -> 1.3861876e+08 | X13: 0.40870536 | Y13: =(X13*$T$3)/(Parameters!B28*Parameters!$B$12) -> 0.0031591307 | Z13: =$T$3*X13 -> 1.7961214e+08 | AC13: =Parameters!B28*Parameters!$B$12 -> 56854923840 | AD13: =$AD$3*Parameters!F28 -> 1989582.7 | AE13: =AC13+AD13-W13 -> 5.6718295e+10 | AF13: =AC13+AD13-Z13 -> 5.6677301e+10 | AG13: =($AA$3/10)+(Parameters!F29*$I$3) -> 272842.35 | AH13: =AE13/AG13 -> 207879.37 | AI13: =AF13/AG13 -> 207729.12 | AJ13: =(POWER(AH13, -0.26) - 1)/-0.26 -> 3.6867878 | AK13: =(AJ13-$AJ$4)*100 -> 33.584485 | AL13: =LOG(AH13) -> 5.3178114 | AM13: =(POWER(AI13, -0.26) - 1)/-0.26 -> 3.6867579 | AN13: =(AM13-$AM$4)*100 -> 33.556765 | AO13: =LOG(AI13) -> 5.3174974 | AQ13: 5.7952123 | AU13: =SQRT(AL13) -> 2.306038 | AY13: 5.7928201 | BC13: =SQRT(AO13) -> 2.3059699
A15: Decile | B15: Year | D15: NZS income per recipient | U15: Tax BAU | X15: Tax Progressive | AA15: Size tax paying group by income group | AC15: Gross income | AE15: Net Income BAU | AF15: Net income Progressive | AG15: Quintile size | AH15: Average income pp BAU | AI15: Average income pp progressive | AJ15: Welfare score BAU | AM15: Welfare score progressive | AP15: SWF BAU | AT15: SWF BAU utility log | AX15: SWF Progressive | BB15: SWF Progressive utility CRRA
B16: Year | C16: Years since base | D16: Base year annual rate singles | E16: Base year annual rate couples | F16: Mulitplier | G16: Current year real rate singles | H16: Current year annual rate couples | I16: 65+ employed population current year | J16: Single | K16: In a relationship | L16: NZS paid singles rate | M16: NZS paid couples rate | N16: NZS paid total to employed 65+ | O16: Total 65+ population | P16: Single | Q16: In a relationship | R16: NZS paid singles rate | S16: NZS paid couples rate | T16: NZS paid total to 65+ | U16: Revenue share | V16: Implied average tax rate | W16: Decile NZS cost | X16: Revenue share | Y16: Implied average tax rate | Z16: Decile NZS cost | AA16: Employed working age pop current year | AB16: Total tax paying population | AC16: Employment income | AD16: Pension income | AE16: Total income | AF16: Total income | AJ16: CRRA | AK16: BAU Welfare Normalised | AL16: BAU alternate utility | AM16: CRRA | AN16: Progressive Welfare Normalised | AO16: Progressive alternate utility | AP16: Utilitarian | AQ16: Adjusted score | AR16: Prioritarian | AS16: Maximin | AT16: Utilitarian | AU16: Adjusted score | AV16: Prioritarian | AW16: Maximin | AX16: Utilitarian | AY16: Adjusted score | AZ16: Prioritarian | BA16: Maximin | BB16: Utilitarian | BC16: Adjusted score | BD16: Prioritarian | BE16: Maximin
A17: Overall | B17: 2040 | C17: 15 | D17: =Parameters!$B$7 -> 538.42 | E17: =Parameters!$B$8 -> 414.17 | F17: =Parameters!$B$12 -> 1.01088 | G17: =D17*POWER(F17,C17) -> 633.3084 | H17: =E17*POWER(F17,C17) -> 487.16121 | I17: =Parameters!B5*'Population Projections'!B4 -> 320687.1 | J17: =I17*Parameters!$B$14 -> 134688.58 | K17: =I17*Parameters!$B$13 -> 185998.52 | L17: =J17*G17 -> 85299410 | M17: =K17*H17 -> 90611263 | N17: =M17+L17 -> 1.7591067e+08 | O17: ='Population Projections'!B4 -> 1287900 | P17: =O17*Parameters!$B$14 -> 540918 | Q17: =O17*Parameters!$B$13 -> 746982 | R17: =P17*G17 -> 3.4256791e+08 | S17: =Q17*H17 -> 3.6390066e+08 | T17: =S17+R17 -> 7.0646857e+08 | Z17: =SUM(Z18:Z27) -> 7.0646857e+08 | AA17: ='Population Projections'!C4*Parameters!B4 -> 3054491 | AB17: =AA17+I17 -> 3375178.1 | AC17: =SUM(AC18:AC27) -> 2.2865654e+11 | AD17: =N17 -> 1.7591067e+08 | AE17: =AC17+AD17-W17 -> 2.2883245e+11 | AF17: =AC17+AD17-Z17 -> 2.2812598e+11 | AP17: =SUM(AK18:AK27) -> 242.72756 | AR17: =SUM(AQ18:AQ27) -> 46.514193 | AS17: =MIN(AJ18:AJ27) -> 3.3496684 | AT17: =SUM(AL18:AL27) -> 46.316961 | AV17: =SUM(AU18:AU27) -> 21.484465 | AW17: =MIN(AL18:AL27) -> 3.4196928 | AX17: =SUM(AN18:AN27) -> 242.46076 | AZ17: =SUM(AY18:AY27) -> 46.488678 | BA17: =MIN(AM18:AM27) -> 3.3500121 | BB17: =SUM(AO18:AO27) -> 46.320508 | BD17: =SUM(BC17:BC27) -> 21.485357 | BE17: =MIN(AO18:AO27) -> 3.4208496
A18: 1 | U18: {=Parameters!D19:D28} -> 0.0036096394 | V18: =(U18*$T$17)/(Parameters!B19*POWER(Parameters!$B$12, $C$17)) -> 0.0027164723 | W18: =$T$17*U18 -> 2550096.8 | X18: =Parameters!E19 -> 0 | Y18: =(X18*$T$17)/(Parameters!B19*POWER(Parameters!$B$12, $C$17)) -> 0 | Z18: =$T$17*X18 -> 0 | AC18: =Parameters!B19*POWER(Parameters!$B$12, $C$17) -> 9.3875308e+08 | AD18: =$AD$3*Parameters!F19 -> 19895827 | AE18: =AC18+AD18-W18 -> 9.5609881e+08 | AF18: =AC18+AD18-Z18 -> 9.5864891e+08 | AG18: =($AA$17/10) + (Parameters!F19*$I$17) -> 363755.85 | AH18: =AE18/AG18 -> 2628.4081 | AI18: =AF18/AG18 -> 2635.4186 | AJ18: =(POWER(AH18, -0.26) - 1)/-0.26 -> 3.3496684 | AK18: =(AJ18-$AJ$18)*100 -> 0 | AL18: =LOG(AH18) -> 3.4196928 | AM18: =(POWER(AI18, -0.26) - 1)/-0.26 -> 3.3500121 | AN18: =(AM18-$AM$18)*100 -> 0 | AO18: =LOG(AI18) -> 3.4208496 | AQ18: {=SQRT(AK18:AK27)} -> 0 | AU18: =SQRT(AL18) -> 1.8492411 | AY18: {=SQRT(AN18:AN27)} -> 0 | BC18: =SQRT(AO18) -> 1.8495539
A19: 2 | U19: 0.014401036 | V19: =(U19*$T$17)/(Parameters!B20*POWER(Parameters!$B$12, $C$17)) -> 0.0023904956 | W19: =$T$17*U19 -> 10173880 | X19: =Parameters!E20 -> 0.0032866726 | Y19: =(X19*$T$17)/(Parameters!B20*POWER(Parameters!$B$12, $C$17)) -> 0.00054557022 | Z19: =$T$17*X19 -> 2321930.9 | AC19: =Parameters!B20*POWER(Parameters!$B$12, $C$17) -> 4.2559708e+09 | AD19: =$AD$3*Parameters!F20 -> 17906244 | AE19: =AC19+AD19-W19 -> 4.2637031e+09 | AF19: =AC19+AD19-Z19 -> 4.2715551e+09 | AG19: =($AA$17/10) + (Parameters!F20*$I$17) -> 357925.17 | AH19: =AE19/AG19 -> 11912.275 | AI19: =AF19/AG19 -> 11934.213 | AJ19: =(POWER(AH19, -0.26) - 1)/-0.26 -> 3.5109816 | AK19: =(AJ19-$AJ$18)*100 -> 16.131322 | AL19: =LOG(AH19) -> 4.0759947 | AM19: =(POWER(AI19, -0.26) - 1)/-0.26 -> 3.5111419 | AN19: =(AM19-$AM$18)*100 -> 16.11298 | AO19: =LOG(AI19) -> 4.0767938 | AQ19: 4.0163817 | AU19: =SQRT(AL19) -> 2.0189093 | AY19: 4.0140977 | BC19: =SQRT(AO19) -> 2.0191072
A20: 3 | U20: 0.031399077 | V20: =(U20*$T$17)/(Parameters!B21*POWER(Parameters!$B$12, $C$17)) -> 0.0024991545 | W20: =$T$17*U20 -> 22182461 | X20: =Parameters!E21 -> 0.010281718 | Y20: =(X20*$T$17)/(Parameters!B21*POWER(Parameters!$B$12, $C$17)) -> 0.00081835532 | Z20: =$T$17*X20 -> 7263710.6 | AC20: =Parameters!B21*POWER(Parameters!$B$12, $C$17) -> 8.8759862e+09 | AD20: =$AD$3*Parameters!F21 -> 15916662 | AE20: =AC20+AD20-W20 -> 8.8697204e+09 | AF20: =AC20+AD20-Z20 -> 8.8846392e+09 | AG20: =($AA$17/10) + (Parameters!F21*$I$17) -> 352094.5 | AH20: =AE20/AG20 -> 25191.307 | AI20: =AF20/AG20 -> 25233.678 | AJ20: =(POWER(AH20, -0.26) - 1)/-0.26 -> 3.5702858 | AK20: =(AJ20-$AJ$18)*100 -> 22.061736 | AL20: =LOG(AH20) -> 4.4012507 | AM20: =(POWER(AI20, -0.26) - 1)/-0.26 -> 3.5704063 | AN20: =(AM20-$AM$18)*100 -> 22.039415 | AO20: =LOG(AI20) -> 4.4019806 | AQ20: 4.6969922 | AU20: =SQRT(AL20) -> 2.0979158 | AY20: 4.6946155 | BC20: =SQRT(AO20) -> 2.0980897
A21: 4 | U21: 0.051692243 | V21: =(U21*$T$17)/(Parameters!B22*POWER(Parameters!$B$12, $C$17)) -> 0.0026078134 | W21: =$T$17*U21 -> 36518945 | X21: =Parameters!E22 -> 0.021628655 | Y21: =(X21*$T$17)/(Parameters!B22*POWER(Parameters!$B$12, $C$17)) -> 0.0010911404 | Z21: =$T$17*X21 -> 15279965 | AC21: =Parameters!B22*POWER(Parameters!$B$12, $C$17) -> 1.4003665e+10 | AD21: =$AD$3*Parameters!F22 -> 13927079 | AE21: =AC21+AD21-W21 -> 1.3981073e+10 | AF21: =AC21+AD21-Z21 -> 1.4002312e+10 | AG21: =($AA$17/10) + (Parameters!F22*$I$17) -> 346263.82 | AH21: =AE21/AG21 -> 40376.938 | AI21: =AF21/AG21 -> 40438.275 | AJ21: =(POWER(AH21, -0.26) - 1)/-0.26 -> 3.6021302 | AK21: =(AJ21-$AJ$18)*100 -> 25.246177 | AL21: =LOG(AH21) -> 4.6061334 | AM21: =(POWER(AI21, -0.26) - 1)/-0.26 -> 3.6022265 | AN21: =(AM21-$AM$18)*100 -> 25.221434 | AO21: =LOG(AI21) -> 4.6067926 | AQ21: 5.0245574 | AU21: =SQRT(AL21) -> 2.1461904 | AY21: 5.0220946 | BC21: =SQRT(AO21) -> 2.146344
A22: 5 | U22: 0.070583126 | V22: =(U22*$T$17)/(Parameters!B23*POWER(Parameters!$B$12, $C$17)) -> 0.0027164723 | W22: =$T$17*U22 -> 49864760 | X22: =Parameters!E23 -> 0.042527271 | Y22: =(X22*$T$17)/(Parameters!B23*POWER(Parameters!$B$12, $C$17)) -> 0.0016367106 | Z22: =$T$17*X22 -> 30044180 | AC22: =Parameters!B23*POWER(Parameters!$B$12, $C$17) -> 1.835644e+10 | AD22: =$AD$3*Parameters!F23 -> 11937496 | AE22: =AC22+AD22-W22 -> 1.8318512e+10 | AF22: =AC22+AD22-Z22 -> 1.8338333e+10 | AG22: =($AA$17/10) + (Parameters!F23*$I$17) -> 340433.15 | AH22: =AE22/AG22 -> 53809.426 | AI22: =AF22/AG22 -> 53867.648 | AJ22: =(POWER(AH22, -0.26) - 1)/-0.26 -> 3.6196876 | AK22: =(AJ22-$AJ$18)*100 -> 27.00192 | AL22: =LOG(AH22) -> 4.7308584 | AM22: =(POWER(AI22, -0.26) - 1)/-0.26 -> 3.6197513 | AN22: =(AM22-$AM$18)*100 -> 26.973915 | AO22: =LOG(AI22) -> 4.731328 | AQ22: 5.1963372 | AU22: =SQRT(AL22) -> 2.1750536 | AY22: 5.1936418 | BC22: =SQRT(AO22) -> 2.1751616
A23: 6 | U23: 0.090905111 | V23: =(U23*$T$17)/(Parameters!B24*POWER(Parameters!$B$12, $C$17)) -> 0.0029337901 | W23: =$T$17*U23 -> 64221603 | X23: =Parameters!E24 -> 0.067619181 | Y23: =(X23*$T$17)/(Parameters!B24*POWER(Parameters!$B$12, $C$17)) -> 0.0021822809 | Z23: =$T$17*X23 -> 47770826 | AC23: =Parameters!B24*POWER(Parameters!$B$12, $C$17) -> 2.189032e+10 | AD23: =$AD$3*Parameters!F24 -> 9947913.5 | AE23: =AC23+AD23-W23 -> 2.1836046e+10 | AF23: =AC23+AD23-Z23 -> 2.1852497e+10 | AG23: =($AA$17/10) + (Parameters!F24*$I$17) -> 334602.47 | AH23: =AE23/AG23 -> 65259.667 | AI23: =AF23/AG23 -> 65308.832 | AJ23: =(POWER(AH23, -0.26) - 1)/-0.26 -> 3.6307671 | AK23: =(AJ23-$AJ$18)*100 -> 28.10987 | AL23: =LOG(AH23) -> 4.8146449 | AM23: =(POWER(AI23, -0.26) - 1)/-0.26 -> 3.6308093 | AN23: =(AM23-$AM$18)*100 -> 28.079715 | AO23: =LOG(AI23) -> 4.8149719 | AQ23: 5.3018742 | AU23: =SQRT(AL23) -> 2.1942299 | AY23: 5.2990296 | BC23: =SQRT(AO23) -> 2.1943044
A24: 7 | U24: 0.11035602 | V24: =(U24*$T$17)/(Parameters!B25*POWER(Parameters!$B$12, $C$17)) -> 0.003042449 | W24: =$T$17*U24 -> 77963062 | X24: =Parameters!E25 -> 0.098944896 | Y24: =(X24*$T$17)/(Parameters!B25*POWER(Parameters!$B$12, $C$17)) -> 0.0027278511 | Z24: =$T$17*X24 -> 69901459 | AC24: =Parameters!B25*POWER(Parameters!$B$12, $C$17) -> 2.5625101e+10 | AD24: =$AD$3*Parameters!F25 -> 7958330.8 | AE24: =AC24+AD24-W24 -> 2.5555096e+10 | AF24: =AC24+AD24-Z24 -> 2.5563158e+10 | AG24: =($AA$17/10) + (Parameters!F25*$I$17) -> 328771.8 | AH24: =AE24/AG24 -> 77728.979 | AI24: =AF24/AG24 -> 77753.499 | AJ24: =(POWER(AH24, -0.26) - 1)/-0.26 -> 3.6403398 | AK24: =(AJ24-$AJ$18)*100 -> 29.067137 | AL24: =LOG(AH24) -> 4.890583 | AM24: =(POWER(AI24, -0.26) - 1)/-0.26 -> 3.6403566 | AN24: =(AM24-$AM$18)*100 -> 29.034453 | AO24: =LOG(AI24) -> 4.8907199 | AQ24: 5.3913947 | AU24: =SQRT(AL24) -> 2.2114662 | AY24: 5.3883627 | BC24: =SQRT(AO24) -> 2.2114972
A25: 8 | U25: 0.13623162 | V25: =(U25*$T$17)/(Parameters!B26*POWER(Parameters!$B$12, $C$17)) -> 0.0031511079 | W25: =$T$17*U25 -> 96243355 | X25: =Parameters!E26 -> 0.14151958 | Y25: =(X25*$T$17)/(Parameters!B26*POWER(Parameters!$B$12, $C$17)) -> 0.0032734213 | Z25: =$T$17*X25 -> 99979137 | AC25: =Parameters!B26*POWER(Parameters!$B$12, $C$17) -> 3.0542704e+10 | AD25: =$AD$3*Parameters!F26 -> 5968748.1 | AE25: =AC25+AD25-W25 -> 3.0452429e+10 | AF25: =AC25+AD25-Z25 -> 3.0448693e+10 | AG25: =($AA$17/10) + (Parameters!F26*$I$17) -> 322941.12 | AH25: =AE25/AG25 -> 94297.155 | AI25: =AF25/AG25 -> 94285.587 | AJ25: =(POWER(AH25, -0.26) - 1)/-0.26 -> 3.650424 | AK25: =(AJ25-$AJ$18)*100 -> 30.075562 | AL25: =LOG(AH25) -> 4.9744986 | AM25: =(POWER(AI25, -0.26) - 1)/-0.26 -> 3.6504178 | AN25: =(AM25-$AM$18)*100 -> 30.040566 | AO25: =LOG(AI25) -> 4.9744453 | AQ25: 5.4841191 | AU25: =SQRT(AL25) -> 2.2303584 | AY25: 5.4809274 | BC25: =SQRT(AO25) -> 2.2303465
A26: 9 | U26: 0.17539672 | V26: =(U26*$T$17)/(Parameters!B27*POWER(Parameters!$B$12, $C$17)) -> 0.0032597668 | W26: =$T$17*U26 -> 1.2391227e+08 | X26: =Parameters!E27 -> 0.20548666 | Y26: =(X26*$T$17)/(Parameters!B27*POWER(Parameters!$B$12, $C$17)) -> 0.0038189915 | Z26: =$T$17*X26 -> 1.4516987e+08 | AC26: =Parameters!B27*POWER(Parameters!$B$12, $C$17) -> 3.8012619e+10 | AD26: =$AD$3*Parameters!F27 -> 3979165.4 | AE26: =AC26+AD26-W26 -> 3.7892686e+10 | AF26: =AC26+AD26-Z26 -> 3.7871428e+10 | AG26: =($AA$17/10) + (Parameters!F27*$I$17) -> 317110.45 | AH26: =AE26/AG26 -> 119493.65 | AI26: =AF26/AG26 -> 119426.62 | AJ26: =(POWER(AH26, -0.26) - 1)/-0.26 -> 3.6621118 | AK26: =(AJ26-$AJ$18)*100 -> 31.244343 | AL26: =LOG(AH26) -> 5.0773448 | AM26: =(POWER(AI26, -0.26) - 1)/-0.26 -> 3.662085 | AN26: =(AM26-$AM$18)*100 -> 31.207285 | AO26: =LOG(AI26) -> 5.0771011 | AQ26: 5.5896639 | AU26: =SQRT(AL26) -> 2.2532964 | AY26: 5.5863481 | BC26: =SQRT(AO26) -> 2.2532424
A27: 10 | U27: 0.3154254 | V27: =(U27*$T$17)/(Parameters!B28*POWER(Parameters!$B$12, $C$17)) -> 0.0033684257 | W27: =$T$17*U27 -> 2.2283813e+08 | X27: =Parameters!E28 -> 0.40870536 | Y27: =(X27*$T$17)/(Parameters!B28*POWER(Parameters!$B$12, $C$17)) -> 0.0043645617 | Z27: =$T$17*X27 -> 2.8873749e+08 | AC27: =Parameters!B28*POWER(Parameters!$B$12, $C$17) -> 6.615498e+10 | AD27: =$AD$3*Parameters!F28 -> 1989582.7 | AE27: =AC27+AD27-W27 -> 6.5934131e+10 | AF27: =AC27+AD27-Z27 -> 6.5868232e+10 | AG27: =($AA$17/10) + (Parameters!F28*$I$17) -> 311279.77 | AH27: =AE27/AG27 -> 211816.3 | AI27: =AF27/AG27 -> 211604.6 | AJ27: =(POWER(AH27, -0.26) - 1)/-0.26 -> 3.6875633 | AK27: =(AJ27-$AJ$18)*100 -> 33.789493 | AL27: =LOG(AH27) -> 5.3259594 | AM27: =(POWER(AI27, -0.26) - 1)/-0.26 -> 3.6875221 | AN27: =(AM27-$AM$18)*100 -> 33.750998 | AO27: =LOG(AI27) -> 5.3255251 | AQ27: 5.8128731 | AU27: =SQRT(AL27) -> 2.307804 | AY27: 5.8095609 | BC27: =SQRT(AO27) -> 2.3077099
A29: Decile | B29: Year | D29: NZS income per recipient | U29: Tax BAU | X29: Tax Progressive | AA29: Size tax paying group by income group | AC29: Gross income | AE29: Net Income BAU | AF29: Net income Progressive | AG29: Quintile size | AH29: Average income pp BAU | AI29: Average income pp progressive | AJ29: Welfare score BAU | AM29: Welfare score progressive | AP29: SWF BAU | AT29: SWF BAU utility log | AX29: SWF Progressive | BB29: SWF Progressive utility CRRA
