Workbook

Sheet Parameters
A1: Parameter | B1: FY 24/25 Value | C1: Notes | D1: Sources | E1: Source notes
A2: EmploymentRate_WorkingAge | B2: 0.781 | C2: fraction of 15–64 employed | D2: https://infoshare.stats.govt.nz/ViewTable.aspx?pxID=a16e84d4-00a9-41d6-8a4a-8bf771bd2d2d | E2: Labour Force Status for people aged 15 to 64 years (Annual-Mar) | Employment rate | 2025
A3: EmploymentRate_65Plus | B3: 0.249 | C3: fraction of 65+ employed | D3: https://infoshare.stats.govt.nz/SelectVariables.aspx?pxID=a3faf5f4-e39a-4dbb-be8e-f81723992bcb | E3: Table: Labour Force Status by Sex by Age Group (Annual-Mar) | Total Both Sexes | Aged 65 years and over | Employment rate | 2025
A4: NZS_Annual single | B4: =519.47*52 -> 27012.44 | C4: net annual NZS per person | D4: https://www.workandincome.govt.nz/map/deskfile/nz-superannuation-and-veterans-pension-tables/new-zealand-superannuation-and-veterans-pension-ra.html
A5: NZS_annual couple | B5: =399.59*52 -> 20778.68 | C5: net annual NZS per person (half couple's rate) | D5: https://www.workandincome.govt.nz/map/deskfile/nz-superannuation-and-veterans-pension-tables/new-zealand-superannuation-and-veterans-pension-ra.html
A6: Average inflation | B6: 0.026 | C6: average 2005-2025 | D6: https://www.stats.govt.nz/news/annual-inflation-at-2-7-percent-in-june-2025/
A7: Average real wage growth | B7: 0.03688 | C7: average 1999-2023 | D7: https://www.stats.govt.nz/news/income-growth-for-wage-and-salary-earners-remains-strong/
A8: Multiplier | B8: =(B7-B6) + 1 -> 1.01088 | C8: Real wage growth - inflation + 1
A9: Ratio 65+ pop partnered | B9: 0.58 | D9: https://explore.data.stats.govt.nz/vis?tm=relationship&pg=0&snb=14&df%5bds%5d=ds-nsiws-disseminate&df%5bid%5d=CEN23_POP_008&df%5bag%5d=STATSNZ&df%5bvs%5d=1.0&dq=2013%2B2018%2B2023.9999%2B99999%2B999999.99...99&to%5bTIME%5d=false
A10: Ratio 65+ pop single | B10: 0.42 | D10: https://explore.data.stats.govt.nz/vis?tm=relationship&pg=0&snb=14&df%5bds%5d=ds-nsiws-disseminate&df%5bid%5d=CEN23_POP_008&df%5bag%5d=STATSNZ&df%5bvs%5d=1.0&dq=2013%2B2018%2B2023.9999%2B99999%2B999999.99...99&to%5bTIME%5d=false
A11: Income from wealth | B11: 0.05
A14: Parameters by Income Decile | B14: Base year total income | C14: Revenue share BAU | D14: Revenue share progressive | E14: Share of employed 65+ population | F14: Weights for share of employed 65+ population
A15: 1 | B15: =798.1*1000000 -> 798100000 | C15: ='Revenue share calc'!E2 -> 0.0036096394 | D15: ='Revenue share calc'!H2 -> 0 | E15: =F15/55 -> 0.18181818 | F15: 10
A16: 2 | B16: =3618.3*1000000 -> 3618300000 | C16: ='Revenue share calc'!E3 -> 0.014401036 | D16: ='Revenue share calc'!H3 -> 0.0034800777 | E16: =F16/55 -> 0.16363636 | F16: 9
A17: 3 | B17: =7546.1*1000000 -> 7546100000 | C17: ='Revenue share calc'!E4 -> 0.031399077 | D17: ='Revenue share calc'!H4 -> 0.010886748 | E17: =F17/55 -> 0.14545455 | F17: 8
A18: 4 | B18: =11905.5*1000000 -> 11905500000 | C18: ='Revenue share calc'!E5 -> 0.051692243 | D18: ='Revenue share calc'!H5 -> 0.022901399 | E18: =F18/55 -> 0.12727273 | F18: 7
A19: 5 | B19: =15606.1*1000000 -> 15606100000 | C19: ='Revenue share calc'!E6 -> 0.070583126 | D19: ='Revenue share calc'!H6 -> 0.037524833 | E19: =F19/55 -> 0.10909091 | F19: 6
A20: 6 | B20: =18610.5*1000000 -> 18610500000 | C20: ='Revenue share calc'!E7 -> 0.090905111 | D20: ='Revenue share calc'!H7 -> 0.053698687 | E20: =F20/55 -> 0.090909091 | F20: 5
A21: 7 | B21: =21785.7*1000000 -> 21785700000 | C21: ='Revenue share calc'!E8 -> 0.11035602 | D21: ='Revenue share calc'!H8 -> 0.083813868 | E21: =F21/55 -> 0.072727273 | F21: 4
A22: 8 | B22: =25966.5*1000000 -> 25966500000 | C22: ='Revenue share calc'!E9 -> 0.13623162 | D22: ='Revenue share calc'!H9 -> 0.13736006 | E22: =F22/55 -> 0.054545455 | F22: 3
A23: 9 | B23: =32317.2*1000000 -> 32317200000 | C23: ='Revenue share calc'!E10 -> 0.17539672 | D23: ='Revenue share calc'!H10 -> 0.21757858 | E23: =F23/55 -> 0.036363636 | F23: 2
A24: 10 | B24: =56243*1000000 -> 56243000000 | C24: ='Revenue share calc'!E11 -> 0.3154254 | D24: ='Revenue share calc'!H11 -> 0.43275574 | E24: =F24/55 -> 0.018181818 | F24: 1
A25: Source: https://www.ird.govt.nz/about-us/tax-statistics/revenue-refunds/wage-salary-distributions/wage-and-salary-statistics-datasets
A28: Wealth base year: FY 23/24
A29: Parameters by Wealth Quintile | B29: Total Wealth | C29: Value of owner-occupied dwelings | D29: Adjusted for negative values+ housing value | E29: Income from wealth | F29: Weighting of 65+ population | G29: Share of 65+ population
A30: 1 | B30: -3546560000 | C30: 11832606000 | D30: 0 | E30: 0 | F30: 1 | G30: =F30/15 -> 0.066666667
A31: 2 | B31: 59384533000 | C31: 39772526000 | D31: =B31-C31 -> 19612007000 | E31: =D31*$B$11 -> 980600350 | F31: 2 | G31: =F31/15 -> 0.13333333
A32: 3 | B32: 213316981000 | C32: 182423471000 | D32: =B32-C32 -> 30893510000 | E32: =D32*$B$11 -> 1544675500 | F32: 3 | G32: =F32/15 -> 0.2
A33: 4 | B33: 426978284000 | C33: 296903566000 | D33: =B33-C33 -> 130074718000 | E33: =D33*$B$11 -> 6503735900 | F33: 4 | G33: =F33/15 -> 0.26666667
A34: 5 | B34: 1371364554000 | C34: 395607963000 | D34: =B34-C34 -> 975756591000 | E34: =D34*$B$11 -> 48787829550 | F34: 5 | G34: =F34/15 -> 0.33333333
A36: Population projections
A37: Year | B37: 65+ | C37: 15-64 | D37: 65+ scaling factor from 2025 | E37: working age scaling factor from base year
A38: 2025 | B38: 902100 | C38: 3465800 | D38: 1 | E38: 1
A39: 2026 | B39: 932200 | C39: 3493500 | D39: =B39/B38 -> 1.0333666 | E39: =C39/$C$38 -> 1.0079924
A40: 2040 | B40: 1287900 | C40: 3911000 | D40: =B40/B38 -> 1.4276688 | E40: =C40/$C$38 -> 1.1284552
A41: 2060 | B41: 1776600 | C41: 4303300 | D41: =B41/B38 -> 1.9694047 | E41: =C41/$C$38 -> 1.241647
A42: 2078 | B42: 2239600 | C42: 4564400 | D42: =B42/B38 -> 2.4826516 | E42: =C42/C38 -> 1.3169831
A43: https://explore.data.stats.govt.nz/vis?fs[0]=Society%2C1%7CPopulation%20projections%23CAT_POPULATION_PROJECTIONS%23%7CNational%20population%20projections%23CAT_NATIONAL_POPULATION_PROJECTIONS%23&pg=0&fc=Society&bp=true&snb=9&df[ds]=ds-nsiws-disseminate&df[id]=POPPR_NAT_007&df[ag]=STATSNZ&df[vs]=1.0&dq=.2025%2B2040%2B2060%2B2078.SEX3.AGE6500%2BAGE4064%2BAGE1539%2BTOTALALLAGES&ly[rw]=YEAR_POPPR_NAT_007&ly[cl]=SCENARIO_POPPR_NAT_007&to[TIME]=false
A44: Based on Median projections
A46: Dependency ratios
...

Sheet Wealth Models
A1: Quintile | B1: Year | E1: NZS income per recipient | P1: Baseline tax | S1: Progressive tax | V1: Gross income | X1: Net Income baseline tax | Z1: Net income Progressive tax | AB1: Utility score baseline tax | AD1: Utility score progressive tax | AF1: Welfare score baesline tax post-NZS income isoelastic utility | AJ1: Welfare score progressive tax post-NZS income isoelastic utility | AN1: Welfare score baesline tax post-NZS income log utility | AR1: Welfare score progressive tax post-NZS income log utility
B2: Year | C2: Years since base NZS | D2: Years since base wealth | E2: Base year annual rate singles | F2: Base year annual rate couples | G2: Mulitplier | H2: Current year real rate singles | I2: Current year annual rate couples | J2: Total 65+ population | K2: Single | L2: In a relationship | M2: NZS paid singles rate | N2: NZS paid couples rate | O2: NZS paid total to 65+ | P2: Revenue share | Q2: Required tax rate | R2: Decile NZS cost | S2: Revenue share | T2: Required tax rate | U2: Decile NZS cost | V2: Wealth income | W2: Pension income | X2: Total income post NZS | Y2: pre-NZS | Z2: Total income post-NZS | AA2: pre-NZS | AB2: Isoelastic p = 1.26 | AC2: Isoelsatic p = 1 | AD2: Isoelastic p = 1.26 | AE2: Isoelsatic p = 1 | AF2: Utilitarian | AG2: Adjusted score | AH2: Prioritarian | AI2: Maximin | AJ2: Utilitarian | AK2: Adjusted score | AL2: Prioritarian | AM2: Maximin | AN2: Utilitarian | AO2: Adjusted score | AP2: Prioritarian | AQ2: Maximin | AR2: Utilitarian | AS2: Adjusted score | AT2: Prioritarian | AU2: Maximin
A3: Overall | B3: 2026 | C3: 2 | D3: 3 | E3: =Parameters!$B$4 -> 27012.44 | F3: =Parameters!$B$5 -> 20778.68 | G3: =Parameters!$B$8 -> 1.01088 | H3: =E3*POWER(G3,C3) -> 27603.428 | I3: =F3*POWER(G3,C3) -> 21233.284 | J3: =Parameters!B39 -> 932200 | K3: =J3*Parameters!$B$10 -> 391524 | L3: =J3*Parameters!$B$9 -> 540676 | M3: =K3*H3 -> 1.0807405e+10 | N3: =L3*I3 -> 1.1480327e+10 | O3: =N3+M3 -> 2.2287732e+10 | R3: =SUM(R4:R8) -> 2.1575807e+10 | U3: =SUM(U4:U13) -> 2.1575807e+10 | V3: =SUM(V4:V8) -> 5.972459e+10 | W3: =SUM(W4:W8) -> 2.2287732e+10 | X3: =V3+W3-R3 -> 6.0436514e+10 | Y3: =V3-R3 -> 3.8148782e+10 | Z3: =V3+W3-U3 -> 6.0436514e+10 | AA3: =V3-U3 -> 3.8148782e+10 | AC3: Sensitivity check | AE3: Sensitivity check | AF3: =SUM(AB4:AB8) -> 19.1748 | AH3: =SUM(AG4:AG8) -> 9.7915261 | AI3: =MIN(AB5:AB8) -> 3.8336413 | AJ3: =SUM(AD4:AD8) -> 19.175203 | AL3: =SUM(AK4:AK8) -> 9.7916291 | AM3: =MIN(AD5:AD8) -> 3.8338069 | AN3: =SUM(AC4:AC8) -> 49.094742 | AP3: =SUM(AO4:AO8) -> 15.663051 | AQ3: =MIN(AC5:AC8) -> 9.5680079 | AR3: =SUM(AE4:AE8) -> 49.151587 | AT3: =SUM(AS4:AS8) -> 15.672206 | AU3: =MIN(AE5:AE8) -> 9.5902539
A4: 1 | P4: ='Revenue share calc'!E18 -> 0 | Q4: 0 | R4: =$O$3*P4 -> 0 | S4: ='Revenue share calc'!H18 -> 0 | T4: 0 | U4: =$O$3*S4 -> 0 | V4: =Parameters!E30*POWER(Parameters!$B$8, $D$3) -> 0 | W4: =$O$3*Parameters!G30 -> 1.4858488e+09 | X4: =V4+W4-R4 -> 1.4858488e+09 | Y4: =V4-R4 -> 0 | Z4: =V4+W4-U4 -> 1.4858488e+09 | AA4: =V4-U4 -> 0 | AB4: =(POWER(X4, -0.26) - 1)/-0.26 -> 3.8302935 | AC4: =LOG(X4) -> 9.1719746 | AD4: =(POWER(Z4, -0.26) - 1)/-0.26 -> 3.8302935 | AE4: =LOG(Z4) -> 9.1719746 | AG4: {=SQRT(AB4:AB8)} -> 1.9571136 | AK4: {=SQRT(AD4:AD8)} -> 1.9571136 | AO4: =SQRT(AC4) -> 3.0285268 | AS4: =SQRT(AE4) -> 3.0285268
A5: 2 | P5: ='Revenue share calc'!E19 -> 0.013269739 | Q5: =(P5*$O$3)/(Parameters!E31*POWER(Parameters!$B$8, $D$3)) -> 0.29196943 | R5: =Q5*Parameters!E31 -> 2.8630533e+08 | S5: ='Revenue share calc'!H19 -> 0.0042606706 | T5: =(S5*$O$3)/(Parameters!E31*POWER(Parameters!$B$8,$D$3)) -> 0.09374605 | U5: =T5*Parameters!E31 -> 91927409 | V5: =Parameters!E31*POWER(Parameters!$B$8, $D$3) -> 1.0129566e+09 | W5: =$O$3*Parameters!G31 -> 2.9716975e+09 | X5: =V5+W5-R5 -> 3.6983489e+09 | Y5: =V5-R5 -> 7.2665131e+08 | Z5: =V5+W5-U5 -> 3.8927268e+09 | AA5: =V5-U5 -> 9.2102923e+08 | AB5: =(POWER(X5, -0.26) - 1)/-0.26 -> 3.8336413 | AC5: =LOG(X5) -> 9.5680079 | AD5: =(POWER(Z5, -0.26) - 1)/-0.26 -> 3.8338069 | AE5: =LOG(Z5) -> 9.5902539 | AG5: 1.9579687 | AK5: 1.9580109 | AO5: =SQRT(AC5) -> 3.0932197 | AS5: =SQRT(AE5) -> 3.0968135
A6: 3 | P6: ='Revenue share calc'!E20 -> 0.023126668 | Q6: =(P6*$O$3)/(Parameters!E32*POWER(Parameters!$B$8, $D$3)) -> 0.32303001 | R6: =Q6*Parameters!E32 -> 4.9897654e+08 | S6: ='Revenue share calc'!H20 -> 0.01054673 | T6: =(S6*$O$3)/(Parameters!E32*POWER(Parameters!$B$8,$D$3)) -> 0.14731522 | U6: =T6*Parameters!E32 -> 2.2755421e+08 | V6: =Parameters!E32*POWER(Parameters!$B$8, $D$3) -> 1.5956442e+09 | W6: =$O$3*Parameters!G32 -> 4.4575463e+09 | X6: =V6+W6-R6 -> 5.554214e+09 | Y6: =V6-R6 -> 1.0966677e+09 | Z6: =V6+W6-U6 -> 5.8256363e+09 | AA6: =V6-U6 -> 1.36809e+09 | AB6: =(POWER(X6, -0.26) - 1)/-0.26 -> 3.8348968 | AC6: =LOG(X6) -> 9.7446226 | AD6: =(POWER(Z6, -0.26) - 1)/-0.26 -> 3.8350356 | AE6: =LOG(Z6) -> 9.7653434 | AG6: 1.9582893 | AK6: 1.9583247 | AO6: =SQRT(AC6) -> 3.1216378 | AS6: =SQRT(AE6) -> 3.1249549
A7: 4 | P7: ='Revenue share calc'!E21 -> 0.10673583 | Q7: =(P7*$O$3)/(Parameters!E33*POWER(Parameters!$B$8, $D$3)) -> 0.35409059 | R7: =Q7*Parameters!E33 -> 2.3029117e+09 | S7: ='Revenue share calc'!H21 -> 0.076701592 | T7: =(S7*$O$3)/(Parameters!E33*POWER(Parameters!$B$8,$D$3)) -> 0.25445356 | U7: =T7*Parameters!E33 -> 1.6548988e+09 | V7: =Parameters!E33*POWER(Parameters!$B$8, $D$3) -> 6.7183358e+09 | W7: =$O$3*Parameters!G33 -> 5.9433951e+09 | X7: =V7+W7-R7 -> 1.0358819e+10 | Y7: =V7-R7 -> 4.4154242e+09 | Z7: =V7+W7-U7 -> 1.1006832e+10 | AA7: =V7-U7 -> 5.0634371e+09 | AB7: =(POWER(X7, -0.26) - 1)/-0.26 -> 3.8365809 | AC7: =LOG(X7) -> 10.01531 | AD7: =(POWER(Z7, -0.26) - 1)/-0.26 -> 3.8367307 | AE7: =LOG(Z7) -> 10.041662 | AG7: 1.9587192 | AK7: 1.9587574 | AO7: =SQRT(AC7) -> 3.1646975 | AS7: =SQRT(AE7) -> 3.1688582
A8: 5 | P8: ='Revenue share calc'!E22 -> 0.85686776 | Q8: =(P8*$O$3)/(Parameters!E34*POWER(Parameters!$B$8, $D$3)) -> 0.37893905 | R8: =Q8*Parameters!E34 -> 1.8487614e+10 | S8: ='Revenue share calc'!H22 -> 0.90849101 | T8: =(S8*$O$3)/(Parameters!E34*POWER(Parameters!$B$8,$D$3)) -> 0.40176878 | U8: =T8*Parameters!E34 -> 1.9601427e+10 | V8: =Parameters!E34*POWER(Parameters!$B$8, $D$3) -> 5.0397653e+10 | W8: =$O$3*Parameters!G34 -> 7.4292439e+09 | X8: =V8+W8-R8 -> 3.9339283e+10 | Y8: =V8-R8 -> 3.1910039e+10 | Z8: =V8+W8-U8 -> 3.822547e+10 | AA8: =V8-U8 -> 3.0796226e+10 | AB8: =(POWER(X8, -0.26) - 1)/-0.26 -> 3.8393872 | AC8: =LOG(X8) -> 10.594826 | AD8: =(POWER(Z8, -0.26) - 1)/-0.26 -> 3.8393365 | AE8: =LOG(Z8) -> 10.582353 | AG8: 1.9594354 | AK8: 1.9594225 | AO8: =SQRT(AC8) -> 3.2549695 | AS8: =SQRT(AE8) -> 3.2530528
A12: Simple means test - top 2 quintiles no NZS
A13: Quintile | B13: Year | E13: NZS income per recipient | P13: Baseline tax | S13: Progressive tax | V13: Gross income | X13: Net Income baseline tax | Z13: Net income Progressive tax | AB13: Utility score baseline tax | AD13: Utility score progressive tax | AF13: Welfare score baesline tax post-NZS income isoelastic utility | AJ13: Welfare score progressive tax post-NZS income isoelastic utility | AN13: Welfare score baesline tax post-NZS income log utility | AR13: Welfare score progressive tax post-NZS income log utility
B14: Year | C14: Years since base NZS | D14: Years since base wealth | E14: Base year annual rate singles | F14: Base year annual rate couples | G14: Mulitplier | H14: Current year real rate singles | I14: Current year annual rate couples | J14: Total 65+ population | K14: Single | L14: In a relationship | M14: NZS paid singles rate | N14: NZS paid couples rate | O14: NZS paid total to 65+ | P14: Revenue share | Q14: Required tax rate | R14: Decile NZS cost | S14: Revenue share | T14: Required tax rate | U14: Decile NZS cost | V14: Wealth income | W14: Pension income after means test | X14: Total income post-NZS | Y14: pre-NZS | Z14: Total income post-NZSs | AA14: pre-NZS | AB14: Isoelastic p = 1.26 | AC14: Isoelsatic p = 1 | AD14: Isoelastic p = 1.26 | AE14: Isoelsatic p = 1 | AF14: Utilitarian | AG14: Adjusted score | AH14: Prioritarian | AI14: Maximin | AJ14: Utilitarian | AK14: Adjusted score | AL14: Prioritarian | AM14: Maximin | AN14: Utilitarian | AO14: Adjusted score | AP14: Prioritarian | AQ14: Maximin | AR14: Utilitarian | AS14: Adjusted score | AT14: Prioritarian | AU14: Maximin
A15: Overall | B15: 2026 | C15: 2 | D15: 3 | E15: =Parameters!$B$4 -> 27012.44 | F15: =Parameters!$B$5 -> 20778.68 | G15: =Parameters!$B$8 -> 1.01088 | H15: =E15*POWER(G15,C15) -> 27603.428 | I15: =F15*POWER(G15,C15) -> 21233.284 | J15: =Parameters!B39 -> 932200 | K15: =J15*Parameters!$B$10 -> 391524 | L15: =J15*Parameters!$B$9 -> 540676 | M15: =K15*H15 -> 1.0807405e+10 | N15: =L15*I15 -> 1.1480327e+10 | O15: =N15+M15 -> 2.2287732e+10 | R15: =SUM(R16:R20) -> 8.9150926e+09 | U15: =SUM(U16:U25) -> 8.9150926e+09 | V15: =SUM(V16:V20) -> 5.972459e+10 | W15: =SUM(W16:W18) -> 8.9150926e+09 | X15: =V15+W15-R15 -> 5.972459e+10 | Y15: =V15-R15 -> 5.0809497e+10 | Z15: =V15+W15-U15 -> 5.972459e+10 | AA15: =V15-U15 -> 5.0809497e+10 | AC15: Sensitivity check | AE15: Sensitivity check | AF15: =SUM(AB16:AB25) -> 19.173663 | AH15: =SUM(AG16:AG20) -> 9.7912359 | AI15: =MIN(AB17:AB25) -> 3.833785 | AJ15: =SUM(AD16:AD20) -> 19.173896 | AL15: =SUM(AK16:AK20) -> 9.7912954 | AM15: =MIN(AD17:AD25) -> 3.833851 | AN15: =SUM(AC16:AC20) -> 48.918167 | AP15: =SUM(AO16:AO20) -> 15.634847 | AQ15: =MIN(AC17:AC20) -> 9.5873015 | AR15: =SUM(AE16:AE20) -> 48.950358 | AT15: =SUM(AS16:AS20) -> 15.640041 | AU15: =MIN(AE17:AE21) -> 9.5962308
A16: 1 | O16: =Parameters!G30*$O$15 -> 1.4858488e+09 | P16: ='Revenue share calc'!E18 -> 0 | Q16: 0 | R16: =P16*SUM($O$16:$O$18) -> 0 | S16: ='Revenue share calc'!H18 -> 0 | T16: 0 | U16: =S16*SUM($O$16:$O$18) -> 0 | V16: =Parameters!E30*POWER(Parameters!$B$8, $D$15) -> 0 | W16: =O16 -> 1.4858488e+09 | X16: =V16+W16-R16 -> 1.4858488e+09 | Y16: =V16-R16 -> 0 | Z16: =V16+W16-U16 -> 1.4858488e+09 | AA16: =V16-U16 -> 0 | AB16: =(POWER(X16, -0.26) - 1)/-0.26 -> 3.8302935 | AC16: =LOG(X16) -> 9.1719746 | AD16: =(POWER(Z16, -0.26) - 1)/-0.26 -> 3.8302935 | AE16: =LOG(Z16) -> 9.1719746 | AG16: =SQRT(AB16) -> 1.9571136 | AK16: =SQRT(AD16) -> 1.9571136 | AO16: =SQRT(AC16) -> 3.0285268 | AS16: =SQRT(AE16) -> 3.0285268
A17: 2 | O17: =Parameters!G31*$O$15 -> 2.9716975e+09 | P17: ='Revenue share calc'!E19 -> 0.013269739 | Q17: =(P17*$O$22)/(Parameters!E31*POWER(Parameters!$B$8,$D$15)) -> 0.11678777 | R17: =P17*SUM($O$16:$O$18) -> 1.1830095e+08 | S17: ='Revenue share calc'!H19 -> 0.0042606706 | T17: =(S17*$O$22)/(Parameters!E31*POWER(Parameters!$B$8,$D$15)) -> 0.03749842 | U17: =S17*SUM($O$16:$O$18) -> 37984273 | V17: =Parameters!E31*POWER(Parameters!$B$8, $D$15) -> 1.0129566e+09 | W17: =O17 -> 2.9716975e+09 | X17: =V17+W17-R17 -> 3.8663532e+09 | Y17: =V17-R17 -> 8.9465569e+08 | Z17: =V17+W17-U17 -> 3.9466699e+09 | AA17: =V17-U17 -> 9.7497237e+08 | AB17: =(POWER(X17, -0.26) - 1)/-0.26 -> 3.833785 | AC17: =LOG(X17) -> 9.5873015 | AD17: =(POWER(Z17, -0.26) - 1)/-0.26 -> 3.833851 | AE17: =LOG(Z17) -> 9.5962308 | AG17: =SQRT(AB17) -> 1.9580054 | AK17: =SQRT(AD17) -> 1.9580222 | AO17: =SQRT(AC17) -> 3.0963368 | AS17: =SQRT(AE17) -> 3.0977784
A18: 3 | O18: =Parameters!G32*$O$15 -> 4.4575463e+09 | P18: ='Revenue share calc'!E20 -> 0.023126668 | Q18: =(P18*$O$22)/(Parameters!E32*POWER(Parameters!$B$8,$D$15)) -> 0.129212 | R18: =P18*SUM($O$16:$O$18) -> 2.0617639e+08 | S18: ='Revenue share calc'!H20 -> 0.01054673 | T18: =(S18*$O$22)/(Parameters!E32*POWER(Parameters!$B$8,$D$15)) -> 0.058926088 | U18: =S18*SUM($O$16:$O$18) -> 94025074 | V18: =Parameters!E32*POWER(Parameters!$B$8, $D$15) -> 1.5956442e+09 | W18: =O18 -> 4.4575463e+09 | X18: =V18+W18-R18 -> 5.8470142e+09 | Y18: =V18-R18 -> 1.3894679e+09 | Z18: =V18+W18-U18 -> 5.9591655e+09 | AA18: =V18-U18 -> 1.5016192e+09 | AB18: =(POWER(X18, -0.26) - 1)/-0.26 -> 3.8350462 | AC18: =LOG(X18) -> 9.7669341 | AD18: =(POWER(Z18, -0.26) - 1)/-0.26 -> 3.8351009 | AE18: =LOG(Z18) -> 9.7751854 | AG18: =SQRT(AB18) -> 1.9583274 | AK18: =SQRT(AD18) -> 1.9583414 | AO18: =SQRT(AC18) -> 3.1252095 | AS18: =SQRT(AE18) -> 3.1265293
A19: 4 | O19: =Parameters!G33*$O$15 -> 5.9433951e+09 | P19: ='Revenue share calc'!E21 -> 0.10673583 | Q19: =(P19*$O$22)/(Parameters!E33*POWER(Parameters!$B$8,$D$15)) -> 0.14163624 | R19: =P19*SUM($O$16:$O$18) -> 9.515598e+08 | S19: ='Revenue share calc'!H21 -> 0.076701592 | T19: =(S19*$O$22)/(Parameters!E33*POWER(Parameters!$B$8,$D$15)) -> 0.10178143 | U19: =S19*SUM($O$16:$O$18) -> 6.838018e+08 | V19: =Parameters!E33*POWER(Parameters!$B$8, $D$15) -> 6.7183358e+09 | W19: 0 | X19: =V19+W19-R19 -> 5.766776e+09 | Y19: =V19-R19 -> 5.766776e+09 | Z19: =V19+W19-U19 -> 6.034534e+09 | AA19: =V19-U19 -> 6.034534e+09 | AB19: =(POWER(X19, -0.26) - 1)/-0.26 -> 3.8350062 | AC19: =LOG(X19) -> 9.7609331 | AD19: =(POWER(Z19, -0.26) - 1)/-0.26 -> 3.8351369 | AE19: =LOG(Z19) -> 9.7806437 | AG19: =SQRT(AB19) -> 1.9583172 | AK19: =SQRT(AD19) -> 1.9583506 | AO19: =SQRT(AC19) -> 3.1242492 | AS19: =SQRT(AE19) -> 3.1274021
A20: 5 | O20: =Parameters!G34*$O$15 -> 7.4292439e+09 | P20: ='Revenue share calc'!E22 -> 0.85686776 | Q20: =(P20*$O$22)/(Parameters!E34*POWER(Parameters!$B$8,$D$15)) -> 0.15157562 | R20: =P20*SUM($O$16:$O$18) -> 7.6390555e+09 | S20: ='Revenue share calc'!H22 -> 0.90849101 | T20: =(S20*$O$22)/(Parameters!E34*POWER(Parameters!$B$8,$D$15)) -> 0.16070751 | U20: =S20*SUM($O$16:$O$18) -> 8.0992815e+09 | V20: =Parameters!E34*POWER(Parameters!$B$8, $D$15) -> 5.0397653e+10 | W20: 0 | X20: =V20+W20-R20 -> 4.2758597e+10 | Y20: =V20-R20 -> 4.2758597e+10 | Z20: =V20+W20-U20 -> 4.2298371e+10 | AA20: =V20-U20 -> 4.2298371e+10 | AB20: =(POWER(X20, -0.26) - 1)/-0.26 -> 3.8395323 | AC20: =LOG(X20) -> 10.631023 | AD20: =(POWER(Z20, -0.26) - 1)/-0.26 -> 3.8395136 | AE20: =LOG(Z20) -> 10.626324 | AG20: =SQRT(AB20) -> 1.9594725 | AK20: =SQRT(AD20) -> 1.9594677 | AO20: =SQRT(AC20) -> 3.260525 | AS20: =SQRT(AE20) -> 3.2598042
N22: NZS paid after means testing: | O22: =SUM(O16:O18) -> 8.9150926e+09

Sheet Income means-test 5 deciles
A1: Decile | B1: Year | D1: NZS income per recipient | V1: Baseline Tax | Y1: Progressive Tax | AB1: Size tax paying group by income group | AD1: Gross income | AF1: Net Income Baseline | AG1: Net income Progressive | AH1: Quintile size | AI1: Average income pp baseline | AK1: Average income pp progressive | AM1: Utility score baseline | AP1: Utility score progressive | AS1: Social welfare function basline tax isoelastic utility | AW1: SWF baseline tax log utility | BA1: SWF progressive tax isoelastic utility | BE1: SWF progressive tax log utility
B2: Year | C2: Years since base | D2: Base year annual rate singles | E2: Base year annual rate couples | F2: Mulitplier | G2: Current year real rate singles | H2: Current year annual rate couples | I2: 65+ employed population current year | J2: Single | K2: In a relationship | L2: NZS paid singles rate | M2: NZS paid couples rate | N2: NZS paid total to employed 65+ | O2: Total 65+ population | P2: Single | Q2: In a relationship | R2: NZS paid singles rate | S2: NZS paid couples rate | T2: NZS paid total to 65+ | U2: NZS paid total after means test | V2: Revenue share | W2: Implied average tax rate | X2: Decile NZS cost | Y2: Revenue share | Z2: Implied average tax rate | AA2: Decile NZS cost | AB2: Employed working age pop current year | AC2: Total tax paying population | AD2: Employment income | AE2: Pension income | AF2: Total income | AG2: Total income | AM2: Isoelastic p=1.26 | AN2: Isoelastic normalised | AO2: Isoelsatic p = 1 | AP2: Isoelastic p=1.26 | AQ2: Isoelastic normalised | AR2: Isoelsatic p = 1 | AS2: Utilitarian | AT2: Adjusted score | AU2: Prioritarian | AV2: Maximin | AW2: Utilitarian | AX2: Adjusted score | AY2: Prioritarian | AZ2: Maximin | BA2: Utilitarian | BB2: Adjusted score | BC2: Prioritarian | BD2: Maximin | BE2: Utilitarian | BF2: Adjusted score | BG2: Prioritarian | BH2: Maximin
A3: Overall | B3: 2026 | C3: 2 | D3: =Parameters!$B$4 -> 27012.44 | E3: =Parameters!$B$5 -> 20778.68 | F3: =Parameters!$B$8 -> 1.01088 | G3: =D3*POWER(F3,C3) -> 27603.428 | H3: =E3*POWER(F3,C3) -> 21233.284 | I3: =Parameters!B3*Parameters!B39 -> 232117.8 | J3: =I3*Parameters!$B$10 -> 97489.476 | K3: =I3*Parameters!$B$9 -> 134628.32 | L3: =J3*G3 -> 2.6910438e+09 | M3: =K3*H3 -> 2.8586014e+09 | N3: =M3+L3 -> 5.5496452e+09 | O3: =Parameters!B39 -> 932200 | P3: =O3*Parameters!$B$10 -> 391524 | Q3: =O3*Parameters!$B$9 -> 540676 | R3: =P3*G3 -> 1.0807405e+10 | S3: =Q3*H3 -> 1.1480327e+10 | T3: =S3+R3 -> 2.2287732e+10 | U3: =T3-SUM(N9:N13) -> 2.0774192e+10 | AA3: =SUM(AA4:AA13) -> 2.0774192e+10 | AB3: =Parameters!C39*Parameters!B2 -> 2728423.5 | AC3: =AB3+I3 -> 2960541.3 | AD3: =SUM(AD4:AD13) -> 1.9865009e+11 | AE3: =N3 -> 5.5496452e+09 | AF3: =AD3+AE3-X3 -> 2.0419974e+11 | AG3: =AD3+AE3-AA3 -> 1.8342554e+11 | AI3: post NZS | AJ3: pre-NZS | AK3: post-NZS | AL3: pre-NZS | AS3: =SUM(AM4:AM13) -> 35.993957 | AT3: Prioriatian | AU3: =SUM(AT4:AT13) -> 18.97128 | AV3: =MIN(AM5:AM13) -> 3.5279445 | AW3: =SUM(AO4:AO13) -> 46.393417 | AX3: Prioriatian | AY3: =SUM(AX4:AX13) -> 21.51785 | AZ3: =MIN(AO5:AO13) -> 4.1627449 | BA3: =SUM(AP4:AP13) -> 36.012333 | BB3: Prioriatian | BC3: =SUM(BB4:BB13) -> 18.976165 | BD3: =MIN(AP5:AP13) -> 3.532164 | BE3: =SUM(AR4:AR13) -> 46.493775 | BF3: Prioriatian | BG3: =SUM(BF3:BF13) -> 21.542261 | BH3: =MIN(AR5:AR13) -> 4.1850424
A4: 1 | N4: =$N$3*Parameters!E15 -> 1.0090264e+09 | V4: =Parameters!C15 -> 0.0036096394 | W4: =(V4*$U$3)/(Parameters!B15*POWER(Parameters!$B$8,$C$3)) -> 0.091945703 | X4: =$U$3*V4 -> 74987341 | Y4: {=Parameters!D15:D24} -> 0 | Z4: =(Y4*$U$3)/(Parameters!B15*POWER(Parameters!$B$8, $C$3)) -> 0 | AA4: =$U$3*Y4 -> 0 | AD4: =Parameters!B15*POWER(Parameters!$B$8,$C$3) -> 8.1556113e+08 | AE4: =$AE$3*Parameters!E15 -> 1.0090264e+09 | AF4: =AD4+AE4-X4 -> 1.7496002e+09 | AG4: =AD4+AE4-AA4 -> 1.8245875e+09 | AH4: =($AB$3+$I$3)/10 -> 296054.13 | AI4: =AF4/AH4 -> 5909.7307 | AJ4: =(AF4-AE4)/AH4 -> 2501.481 | AK4: =AG4/AH4 -> 6163.02 | AL4: =(AG4-AE4)/AH4 -> 2754.7703 | AM4: =(POWER(AI4, -0.26) - 1)/-0.26 -> 3.4439752 | AN4: =(AM4-$AM$4)*100 -> 0 | AO4: =LOG(AI4) -> 3.7715677 | AP4: =(POWER(AK4, -0.26) - 1)/-0.26 -> 3.4483396 | AQ4: =(AP4-$AP$4)*100 -> 0 | AR4: =LOG(AK4) -> 3.7897936 | AT4: =SQRT(AM4) -> 1.855795 | AX4: =SQRT(AO4) -> 1.9420524 | BB4: {=SQRT(AP4:AP13)} -> 1.8569705 | BF4: =SQRT(AR4) -> 1.9467392
A5: 2 | N5: =$N$3*Parameters!E16 -> 9.0812375e+08 | V5: =Parameters!C16 -> 0.014401036 | W5: =(V5*$U$3)/(Parameters!B16*POWER(Parameters!$B$8,$C$3)) -> 0.080912218 | X5: =$U$3*V5 -> 2.991699e+08 | Y5: 0.0034800777 | Z5: =(Y5*$U$3)/(Parameters!B16*POWER(Parameters!$B$8, $C$3)) -> 0.019552816 | AA5: =$U$3*Y5 -> 72295803 | AD5: =Parameters!B16*POWER(Parameters!$B$8,$C$3) -> 3.6974625e+09 | AE5: =$AE$3*Parameters!E16 -> 9.0812375e+08 | AF5: =AD5+AE5-X5 -> 4.3064164e+09 | AG5: =AD5+AE5-AA5 -> 4.5332905e+09 | AH5: =($AB$3+$I$3)/10 -> 296054.13 | AI5: =AF5/AH5 -> 14546.044 | AJ5: =(AF5-AE5)/AH5 -> 11478.619 | AK5: =AG5/AH5 -> 15312.37 | AL5: =(AG5-AE5)/AH5 -> 12244.946 | AM5: =(POWER(AI5, -0.26) - 1)/-0.26 -> 3.5279445 | AN5: =(AM5-$AM$4)*100 -> 8.3969306 | AO5: =LOG(AI5) -> 4.1627449 | AP5: =(POWER(AK5, -0.26) - 1)/-0.26 -> 3.532164 | AQ5: =(AP5-$AP$4)*100 -> 8.3824378 | AR5: =LOG(AK5) -> 4.1850424 | AT5: =SQRT(AM5) -> 1.8782823 | AX5: =SQRT(AO5) -> 2.0402806 | BB5: 1.8794052 | BF5: =SQRT(AR5) -> 2.0457376
A6: 3 | N6: =$N$3*Parameters!E17 -> 8.0722111e+08 | V6: =Parameters!C17 -> 0.031399077 | W6: =(V6*$U$3)/(Parameters!B17*POWER(Parameters!$B$8,$C$3)) -> 0.084590046 | X6: =$U$3*V6 -> 6.5229046e+08 | Y6: 0.010886748 | Z6: =(Y6*$U$3)/(Parameters!B17*POWER(Parameters!$B$8, $C$3)) -> 0.029329224 | AA6: =$U$3*Y6 -> 2.261634e+08 | AD6: =Parameters!B17*POWER(Parameters!$B$8,$C$3) -> 7.7111964e+09 | AE6: =$AE$3*Parameters!E17 -> 8.0722111e+08 | AF6: =AD6+AE6-X6 -> 7.8661271e+09 | AG6: =AD6+AE6-AA6 -> 8.2922541e+09 | AH6: =($AB$3+$I$3)/10 -> 296054.13 | AI6: =AF6/AH6 -> 26569.895 | AJ6: =(AF6-AE6)/AH6 -> 23843.295 | AK6: =AG6/AH6 -> 28009.25 | AL6: =(AG6-AE6)/AH6 -> 25282.65 | AM6: =(POWER(AI6, -0.26) - 1)/-0.26 -> 3.5740809 | AN6: =(AM6-$AM$4)*100 -> 13.010578 | AO6: =LOG(AI6) -> 4.4243898 | AP6: =(POWER(AK6, -0.26) - 1)/-0.26 -> 3.5777874 | AQ6: =(AP6-$AP$4)*100 -> 12.944776 | AR6: =LOG(AK6) -> 4.4473015 | AT6: =SQRT(AM6) -> 1.890524 | AX6: =SQRT(AO6) -> 2.1034234 | BB6: 1.891504 | BF6: =SQRT(AR6) -> 2.1088626
A7: 4 | N7: =$N$3*Parameters!E18 -> 7.0631848e+08 | V7: =Parameters!C18 -> 0.051692243 | W7: =(V7*$U$3)/(Parameters!B18*POWER(Parameters!$B$8,$C$3)) -> 0.088267875 | X7: =$U$3*V7 -> 1.0738646e+09 | Y7: 0.022901399 | Z7: =(Y7*$U$3)/(Parameters!B18*POWER(Parameters!$B$8, $C$3)) -> 0.039105631 | AA7: =$U$3*Y7 -> 4.7575806e+08 | AD7: =Parameters!B18*POWER(Parameters!$B$8,$C$3) -> 1.2165973e+10 | AE7: =$AE$3*Parameters!E18 -> 7.0631848e+08 | AF7: =AD7+AE7-X7 -> 1.1798427e+10 | AG7: =AD7+AE7-AA7 -> 1.2396533e+10 | AH7: =($AB$3+$I$3)/10 -> 296054.13 | AI7: =AF7/AH7 -> 39852.262 | AJ7: =(AF7-AE7)/AH7 -> 37466.488 | AK7: =AG7/AH7 -> 41872.523 | AL7: =(AG7-AE7)/AH7 -> 39486.748 | AM7: =(POWER(AI7, -0.26) - 1)/-0.26 -> 3.6012989 | AN7: =(AM7-$AM$4)*100 -> 15.732374 | AO7: =LOG(AI7) -> 4.600453 | AP7: =(POWER(AK7, -0.26) - 1)/-0.26 -> 3.6044269 | AQ7: =(AP7-$AP$4)*100 -> 15.608728 | AR7: =LOG(AK7) -> 4.6219291 | AT7: =SQRT(AM7) -> 1.8977089 | AX7: =SQRT(AO7) -> 2.1448667 | BB7: 1.8985328 | BF7: =SQRT(AR7) -> 2.1498672
A8: 5 | N8: =$N$3*Parameters!E19 -> 6.0541584e+08 | V8: =Parameters!C19 -> 0.070583126 | W8: =(V8*$U$3)/(Parameters!B19*POWER(Parameters!$B$8,$C$3)) -> 0.091945703 | X8: =$U$3*V8 -> 1.4663074e+09 | Y8: 0.037524833 | Z8: =(Y8*$U$3)/(Parameters!B19*POWER(Parameters!$B$8, $C$3)) -> 0.048882039 | AA8: =$U$3*Y8 -> 7.7954809e+08 | AD8: =Parameters!B19*POWER(Parameters!$B$8,$C$3) -> 1.5947536e+10 | AE8: =$AE$3*Parameters!E19 -> 6.0541584e+08 | AF8: =AD8+AE8-X8 -> 1.5086645e+10 | AG8: =AD8+AE8-AA8 -> 1.5773404e+10 | AH8: =($AB$3+$I$3)/10 -> 296054.13 | AI8: =AF8/AH8 -> 50959.075 | AJ8: =(AF8-AE8)/AH8 -> 48914.125 | AK8: =AG8/AH8 -> 53278.783 | AL8: =(AG8-AE8)/AH8 -> 51233.834 | AM8: =(POWER(AI8, -0.26) - 1)/-0.26 -> 3.6164602 | AN8: =(AM8-$AM$4)*100 -> 17.2485 | AO8: =LOG(AI8) -> 4.7072215 | AP8: =(POWER(AK8, -0.26) - 1)/-0.26 -> 3.6191033 | AQ8: =(AP8-$AP$4)*100 -> 17.07637 | AR8: =LOG(AK8) -> 4.7265543 | AT8: =SQRT(AM8) -> 1.9016993 | AX8: =SQRT(AO8) -> 2.1696132 | BB8: 1.9023941 | BF8: =SQRT(AR8) -> 2.174064
A9: 6 | N9: =$N$3*Parameters!E20 -> 5.045132e+08 | V9: =Parameters!C20 -> 0.090905111 | W9: =(V9*$U$3)/(Parameters!B20*POWER(Parameters!$B$8,$C$3)) -> 0.099301359 | X9: =$U$3*V9 -> 1.8884802e+09 | Y9: 0.053698687 | Z9: =(Y9*$U$3)/(Parameters!B20*POWER(Parameters!$B$8, $C$3)) -> 0.058658447 | AA9: =$U$3*Y9 -> 1.1155468e+09 | AD9: =Parameters!B20*POWER(Parameters!$B$8,$C$3) -> 1.9017667e+10 | AF9: =AD9+AE9-X9 -> 1.7129187e+10 | AG9: =AD9+AE9-AA9 -> 1.7902121e+10 | AH9: =($AB$3+$I$3)/10 -> 296054.13 | AI9: =AF9/AH9 -> 57858.295 | AJ9: =(AF9-AE9)/AH9 -> 57858.295 | AK9: =AG9/AH9 -> 60469.079 | AL9: =(AG9-AE9)/AH9 -> 60469.079 | AM9: =(POWER(AI9, -0.26) - 1)/-0.26 -> 3.6239193 | AN9: =(AM9-$AM$4)*100 -> 17.994413 | AO9: =LOG(AI9) -> 4.7623656 | AP9: =(POWER(AK9, -0.26) - 1)/-0.26 -> 3.6264549 | AQ9: =(AP9-$AP$4)*100 -> 17.811529 | AR9: =LOG(AK9) -> 4.7815334 | AT9: =SQRT(AM9) -> 1.9036594 | AX9: =SQRT(AO9) -> 2.1822845 | BB9: 1.9043253 | BF9: =SQRT(AR9) -> 2.1866718
A10: 7 | N10: =$N$3*Parameters!E21 -> 4.0361056e+08 | V10: =Parameters!C21 -> 0.11035602 | W10: =(V10*$U$3)/(Parameters!B21*POWER(Parameters!$B$8,$C$3)) -> 0.10297919 | X10: =$U$3*V10 -> 2.2925572e+09 | Y10: 0.083813868 | Z10: =(Y10*$U$3)/(Parameters!B21*POWER(Parameters!$B$8, $C$3)) -> 0.078211263 | AA10: =$U$3*Y10 -> 1.7411654e+09 | AD10: =Parameters!B21*POWER(Parameters!$B$8,$C$3) -> 2.2262336e+10 | AF10: =AD10+AE10-X10 -> 1.9969778e+10 | AG10: =AD10+AE10-AA10 -> 2.052117e+10 | AH10: =($AB$3+$I$3)/10 -> 296054.13 | AI10: =AF10/AH10 -> 67453.133 | AJ10: =(AF10-AE10)/AH10 -> 67453.133 | AK10: =AG10/AH10 -> 69315.602 | AL10: =(AG10-AE10)/AH10 -> 69315.602 | AM10: =(POWER(AI10, -0.26) - 1)/-0.26 -> 3.6326105 | AN10: =(AM10-$AM$4)*100 -> 18.863531 | AO10: =LOG(AI10) -> 4.8290021 | AP10: =(POWER(AK10, -0.26) - 1)/-0.26 -> 3.6341174 | AQ10: =(AP10-$AP$4)*100 -> 18.577775 | AR10: =LOG(AK10) -> 4.840831 | AT10: =SQRT(AM10) -> 1.9059408 | AX10: =SQRT(AO10) -> 2.1974991 | BB10: 1.9063361 | BF10: =SQRT(AR10) -> 2.2001889
A11: 8 | N11: =$N$3*Parameters!E22 -> 3.0270792e+08 | V11: =Parameters!C22 -> 0.13623162 | W11: =(V11*$U$3)/(Parameters!B22*POWER(Parameters!$B$8,$C$3)) -> 0.10665702 | X11: =$U$3*V11 -> 2.8301017e+09 | Y11: 0.13736006 | Z11: =(Y11*$U$3)/(Parameters!B22*POWER(Parameters!$B$8, $C$3)) -> 0.10754049 | AA11: =$U$3*Y11 -> 2.8535443e+09 | AD11: =Parameters!B22*POWER(Parameters!$B$8,$C$3) -> 2.6534605e+10 | AF11: =AD11+AE11-X11 -> 2.3704503e+10 | AG11: =AD11+AE11-AA11 -> 2.3681061e+10 | AH11: =($AB$3+$I$3)/10 -> 296054.13 | AI11: =AF11/AH11 -> 80068.138 | AJ11: =(AF11-AE11)/AH11 -> 80068.138 | AK11: =AG11/AH11 -> 79988.955 | AL11: =(AG11-AE11)/AH11 -> 79988.955 | AM11: =(POWER(AI11, -0.26) - 1)/-0.26 -> 3.6419203 | AN11: =(AM11-$AM$4)*100 -> 19.794512 | AO11: =LOG(AI11) -> 4.9034597 | AP11: =(POWER(AK11, -0.26) - 1)/-0.26 -> 3.6418677 | AQ11: =(AP11-$AP$4)*100 -> 19.352812 | AR11: =LOG(AK11) -> 4.90303 | AT11: =SQRT(AM11) -> 1.9083816 | AX11: =SQRT(AO11) -> 2.2143757 | BB11: 1.9083678 | BF11: =SQRT(AR11) -> 2.2142787
A12: 9 | N12: =$N$3*Parameters!E23 -> 2.0180528e+08 | V12: =Parameters!C23 -> 0.17539672 | W12: =(V12*$U$3)/(Parameters!B23*POWER(Parameters!$B$8,$C$3)) -> 0.11033484 | X12: =$U$3*V12 -> 3.6437252e+09 | Y12: 0.21757858 | Z12: =(Y12*$U$3)/(Parameters!B23*POWER(Parameters!$B$8, $C$3)) -> 0.13686971 | AA12: =$U$3*Y12 -> 4.5200192e+09 | AD12: =Parameters!B23*POWER(Parameters!$B$8,$C$3) -> 3.3024248e+10 | AF12: =AD12+AE12-X12 -> 2.9380523e+10 | AG12: =AD12+AE12-AA12 -> 2.8504229e+10 | AH12: =($AB$3+$I$3)/10 -> 296054.13 | AI12: =AF12/AH12 -> 99240.374 | AJ12: =(AF12-AE12)/AH12 -> 99240.374 | AK12: =AG12/AH12 -> 96280.463 | AL12: =(AG12-AE12)/AH12 -> 96280.463 | AM12: =(POWER(AI12, -0.26) - 1)/-0.26 -> 3.653007 | AN12: =(AM12-$AM$4)*100 -> 20.903182 | AO12: =LOG(AI12) -> 4.9966884 | AP12: =(POWER(AK12, -0.26) - 1)/-0.26 -> 3.6514804 | AQ12: =(AP12-$AP$4)*100 -> 20.314079 | AR12: =LOG(AK12) -> 4.9835382 | AT12: =SQRT(AM12) -> 1.9112841 | AX12: =SQRT(AO12) -> 2.2353274 | BB12: 1.9108847 | BF12: =SQRT(AR12) -> 2.232384
A13: 10 | N13: =$N$3*Parameters!E24 -> 1.0090264e+08 | V13: =Parameters!C24 -> 0.3154254 | W13: =(V13*$U$3)/(Parameters!B24*POWER(Parameters!$B$8,$C$3)) -> 0.11401267 | X13: =$U$3*V13 -> 6.5527079e+09 | Y13: 0.43275574 | Z13: =(Y13*$U$3)/(Parameters!B24*POWER(Parameters!$B$8, $C$3)) -> 0.15642253 | AA13: =$U$3*Y13 -> 8.9901509e+09 | AD13: =Parameters!B24*POWER(Parameters!$B$8,$C$3) -> 5.7473505e+10 | AF13: =AD13+AE13-X13 -> 5.0920798e+10 | AG13: =AD13+AE13-AA13 -> 4.8483355e+10 | AH13: =($AB$3+$I$3)/10 -> 296054.13 | AI13: =AF13/AH13 -> 171998.27 | AJ13: =(AF13-AE13)/AH13 -> 171998.27 | AK13: =AG13/AH13 -> 163765.17 | AL13: =(AG13-AE13)/AH13 -> 163765.17 | AM13: =(POWER(AI13, -0.26) - 1)/-0.26 -> 3.6787404 | AN13: =(AM13-$AM$4)*100 -> 23.476522 | AO13: =LOG(AI13) -> 5.2355241 | AP13: =(POWER(AK13, -0.26) - 1)/-0.26 -> 3.6765916 | AQ13: =(AP13-$AP$4)*100 -> 22.825203 | AR13: =LOG(AK13) -> 5.2142215 | AT13: =SQRT(AM13) -> 1.9180043 | AX13: =SQRT(AO13) -> 2.2881268 | BB13: 1.917444 | BF13: =SQRT(AR13) -> 2.283467
A15: Decile | B15: Year | D15: NZS income per recipient | V15: Baseline Tax | Y15: Progressive Tax | AB15: Size tax paying group by income group | AD15: Gross income | AF15: Net Income Baseline | AG15: Net income Progressive | AH15: Quintile size | AI15: Average income pp baseline | AK15: Average income pp progressive | AM15: Utility score baseline | AP15: Utility score progressive | AS15: Social welfare function basline tax isoelastic utility | AW15: SWF baseline tax log utility | BA15: SWF progressive tax isoelastic utility | BE15: SWF progressive tax log utility
B16: Year | C16: Years since base | D16: Base year annual rate singles | E16: Base year annual rate couples | F16: Mulitplier | G16: Current year real rate singles | H16: Current year annual rate couples | I16: 65+ employed population current year | J16: Single | K16: In a relationship | L16: NZS paid singles rate | M16: NZS paid couples rate | N16: NZS paid total to employed 65+ | O16: Total 65+ population | P16: Single | Q16: In a relationship | R16: NZS paid singles rate | S16: NZS paid couples rate | T16: NZS paid total to 65+ | U16: NZS paid total after means test | V16: Revenue share | W16: Implied average tax rate | X16: Decile NZS cost | Y16: Revenue share | Z16: Implied average tax rate | AA16: Decile NZS cost | AB16: Employed working age pop current year | AC16: Total tax paying population | AD16: Employment income | AE16: Pension income | AF16: Total income | AG16: Total income | AM16: Isoelastic p=1.26 | AN16: Isoelastic normalised | AO16: Isoelsatic p = 1 | AP16: Isoelastic p=1.26 | AQ16: Isoelastic normalised | AR16: Isoelsatic p = 1 | AS16: Utilitarian | AT16: Adjusted score | AU16: Prioritarian | AV16: Maximin | AW16: Utilitarian | AX16: Adjusted score | AY16: Prioritarian | AZ16: Maximin | BA16: Utilitarian | BB16: Adjusted score | BC16: Prioritarian | BD16: Maximin | BE16: Utilitarian | BF16: Adjusted score | BG16: Prioritarian | BH16: Maximin
A17: Overall | B17: 2040 | C17: 16 | D17: =Parameters!$B$4 -> 27012.44 | E17: =Parameters!$B$5 -> 20778.68 | F17: =Parameters!$B$8 -> 1.01088 | G17: =D17*POWER(F17,C17) -> 32118.665 | H17: =E17*POWER(F17,C17) -> 24706.523 | I17: =Parameters!B3*Parameters!B40 -> 320687.1 | J17: =I17*Parameters!$B$10 -> 134688.58 | K17: =I17*Parameters!$B$9 -> 185998.52 | L17: =J17*G17 -> 4.3260174e+09 | M17: =K17*H17 -> 4.5953766e+09 | N17: =M17+L17 -> 8.921394e+09 | O17: =Parameters!B40 -> 1287900 | P17: =O17*Parameters!$B$10 -> 540918 | Q17: =O17*Parameters!$B$9 -> 746982 | R17: =P17*G17 -> 1.7373564e+10 | S17: =Q17*H17 -> 1.8455328e+10 | T17: =S17+R17 -> 3.5828892e+10 | U17: =T17-SUM(N23:N27) -> 3.3395784e+10 | AA17: =SUM(AA18:AA27) -> 3.3395784e+10 | AB17: =Parameters!C40*Parameters!B2 -> 3054491 | AC17: =AB17+I17 -> 3375178.1 | AD17: =SUM(AD18:AD27) -> 2.3114432e+11 | AE17: =N17 -> 8.921394e+09 | AF17: =AD17+AE17-X17 -> 2.4006571e+11 | AG17: =AD17+AE17-AA17 -> 2.0666993e+11 | AS17: =SUM(AN18:AN27) -> 161.75946 | AT17: Prioriatian | AU17: =SUM(AT18:AT27) -> 18.965071 | AV17: =MIN(AM19:AM27) -> 3.5248376 | AW17: =SUM(AO18:AO27) -> 46.2526 | AX17: Prioriatian | AY17: =SUM(AX18:AX27) -> 21.484384 | AZ17: =MIN(AO19:AO27) -> 4.1465154 | BA17: =SUM(AQ18:AQ27) -> 157.70466 | BB17: Prioriatian | BC17: =SUM(BB18:BB27) -> 18.972193 | BD17: =MIN(AP19:AP27) -> 3.5309841 | BE17: =SUM(AR18:AR27) -> 46.396815 | BF17: Prioriatian | BG17: =SUM(BF17:BF27) -> 21.519555 | BH17: =MIN(AR19:AR27) -> 4.1787776
A18: 1 | N18: =$N$17*Parameters!E15 -> 1.6220716e+09 | V18: {=Parameters!C15:C24} -> 0.0036096394 | W18: =(V18*$U$17)/(Parameters!B15*POWER(Parameters!$B$8, $C$17)) -> 0.12702947 | X18: =$U$17*V18 -> 1.2054674e+08 | Y18: =Parameters!D15 -> 0 | Z18: =(Y18*$U$17)/(Parameters!B15*POWER(Parameters!$B$8, $C$17)) -> 0 | AA18: =$U$17*Y18 -> 0 | AD18: =Parameters!B15*POWER(Parameters!$B$8, $C$17) -> 9.4896671e+08 | AE18: =$AE$3*Parameters!E15 -> 1.0090264e+09 | AF18: =AD18+AE18-X18 -> 1.8374464e+09 | AG18: =AD18+AE18-AA18 -> 1.9579931e+09 | AH18: =($AB$17+$I$17)/10 -> 337517.81 | AI18: =AF18/AH18 -> 5443.9983 | AK18: =AG18/AH18 -> 5801.1549 | AM18: =(POWER(AI18, -0.26) - 1)/-0.26 -> 3.4352994 | AN18: =(AM18-$AM$18)*100 -> 0 | AO18: =LOG(AI18) -> 3.735918 | AP18: =(POWER(AK18, -0.26) - 1)/-0.26 -> 3.4420315 | AQ18: =(AP18-$AP$18)*100 -> 0 | AR18: =LOG(AK18) -> 3.7635145 | AT18: {=SQRT(AM18:AM27)} -> 1.8534561 | AX18: =SQRT(AO18) -> 1.9328523 | BB18: {=SQRT(AP18:AP27)} -> 1.8552713 | BF18: =SQRT(AR18) -> 1.939978
A19: 2 | N19: =$N$17*Parameters!E16 -> 1.4598645e+09 | V19: 0.014401036 | W19: =(V19*$U$17)/(Parameters!B16*POWER(Parameters!$B$8, $C$17)) -> 0.11178593 | X19: =$U$17*V19 -> 4.809339e+08 | Y19: =Parameters!D16 -> 0.0034800777 | Z19: =(Y19*$U$17)/(Parameters!B16*POWER(Parameters!$B$8, $C$17)) -> 0.027013593 | AA19: =$U$17*Y19 -> 1.1621993e+08 | AD19: =Parameters!B16*POWER(Parameters!$B$8, $C$17) -> 4.3022757e+09 | AE19: =$AE$3*Parameters!E16 -> 9.0812375e+08 | AF19: =AD19+AE19-X19 -> 4.7294656e+09 | AG19: =AD19+AE19-AA19 -> 5.0941796e+09 | AH19: =($AB$17+$I$17)/10 -> 337517.81 | AI19: =AF19/AH19 -> 14012.492 | AK19: =AG19/AH19 -> 15093.069 | AM19: =(POWER(AI19, -0.26) - 1)/-0.26 -> 3.5248376 | AN19: =(AM19-$AM$18)*100 -> 8.953821 | AO19: =LOG(AI19) -> 4.1465154 | AP19: =(POWER(AK19, -0.26) - 1)/-0.26 -> 3.5309841 | AQ19: =(AP19-$AP$18)*100 -> 8.8952649 | AR19: =LOG(AK19) -> 4.1787776 | AT19: 1.8774551 | AX19: =SQRT(AO19) -> 2.0362994 | BB19: 1.8790913 | BF19: =SQRT(AR19) -> 2.0442058
A20: 3 | N20: =$N$17*Parameters!E17 -> 1.2976573e+09 | V20: 0.031399077 | W20: =(V20*$U$17)/(Parameters!B17*POWER(Parameters!$B$8, $C$17)) -> 0.11686711 | X20: =$U$17*V20 -> 1.0485968e+09 | Y20: =Parameters!D17 -> 0.010886748 | Z20: =(Y20*$U$17)/(Parameters!B17*POWER(Parameters!$B$8, $C$17)) -> 0.040520389 | AA20: =$U$17*Y20 -> 3.635715e+08 | AD20: =Parameters!B17*POWER(Parameters!$B$8, $C$17) -> 8.972557e+09 | AE20: =$AE$3*Parameters!E17 -> 8.0722111e+08 | AF20: =AD20+AE20-X20 -> 8.7311813e+09 | AG20: =AD20+AE20-AA20 -> 9.4162066e+09 | AH20: =($AB$17+$I$17)/10 -> 337517.81 | AI20: =AF20/AH20 -> 25868.802 | AK20: =AG20/AH20 -> 27898.399 | AM20: =(POWER(AI20, -0.26) - 1)/-0.26 -> 3.5721827 | AN20: =(AM20-$AM$18)*100 -> 13.68833 | AO20: =LOG(AI20) -> 4.4127763 | AP20: =(POWER(AK20, -0.26) - 1)/-0.26 -> 3.5775105 | AQ20: =(AP20-$AP$18)*100 -> 13.547905 | AR20: =LOG(AK20) -> 4.4455793 | AT20: 1.8900219 | AX20: =SQRT(AO20) -> 2.1006609 | BB20: 1.8914308 | BF20: =SQRT(AR20) -> 2.1084542
A21: 4 | N21: =$N$17*Parameters!E18 -> 1.1354501e+09 | V21: 0.051692243 | W21: =(V21*$U$17)/(Parameters!B18*POWER(Parameters!$B$8, $C$17)) -> 0.12194829 | X21: =$U$17*V21 -> 1.726303e+09 | Y21: =Parameters!D18 -> 0.022901399 | Z21: =(Y21*$U$17)/(Parameters!B18*POWER(Parameters!$B$8, $C$17)) -> 0.054027186 | AA21: =$U$17*Y21 -> 7.6481017e+08 | AD21: =Parameters!B18*POWER(Parameters!$B$8, $C$17) -> 1.4156025e+10 | AE21: =$AE$3*Parameters!E18 -> 7.0631848e+08 | AF21: =AD21+AE21-X21 -> 1.313604e+10 | AG21: =AD21+AE21-AA21 -> 1.4097533e+10 | AH21: =($AB$17+$I$17)/10 -> 337517.81 | AI21: =AF21/AH21 -> 38919.546 | AK21: =AG21/AH21 -> 41768.264 | AM21: =(POWER(AI21, -0.26) - 1)/-0.26 -> 3.5997866 | AN21: =(AM21-$AM$18)*100 -> 16.448715 | AO21: =LOG(AI21) -> 4.5901678 | AP21: =(POWER(AK21, -0.26) - 1)/-0.26 -> 3.6042702 | AQ21: =(AP21-$AP$18)*100 -> 16.223868 | AR21: =LOG(AK21) -> 4.6208464 | AT21: 1.8973104 | AX21: =SQRT(AO21) -> 2.1424677 | BB21: 1.8984915 | BF21: =SQRT(AR21) -> 2.1496154
A22: 5 | N22: =$N$17*Parameters!E19 -> 9.7324298e+08 | V22: 0.070583126 | W22: =(V22*$U$17)/(Parameters!B19*POWER(Parameters!$B$8, $C$17)) -> 0.12702947 | X22: =$U$17*V22 -> 2.3571788e+09 | Y22: =Parameters!D19 -> 0.037524833 | Z22: =(Y22*$U$17)/(Parameters!B19*POWER(Parameters!$B$8, $C$17)) -> 0.067533982 | AA22: =$U$17*Y22 -> 1.2531712e+09 | AD22: =Parameters!B19*POWER(Parameters!$B$8, $C$17) -> 1.8556158e+10 | AE22: =$AE$3*Parameters!E19 -> 6.0541584e+08 | AF22: =AD22+AE22-X22 -> 1.6804395e+10 | AG22: =AD22+AE22-AA22 -> 1.7908402e+10 | AH22: =($AB$17+$I$17)/10 -> 337517.81 | AI22: =AF22/AH22 -> 49788.172 | AK22: =AG22/AH22 -> 53059.133 | AM22: =(POWER(AI22, -0.26) - 1)/-0.26 -> 3.6150677 | AN22: =(AM22-$AM$18)*100 -> 17.976832 | AO22: =LOG(AI22) -> 4.6971262 | AP22: =(POWER(AK22, -0.26) - 1)/-0.26 -> 3.6188593 | AQ22: =(AP22-$AP$18)*100 -> 17.682782 | AR22: =LOG(AK22) -> 4.7247601 | AT22: 1.9013331 | AX22: =SQRT(AO22) -> 2.1672854 | BB22: 1.90233 | BF22: =SQRT(AR22) -> 2.1736513
A23: 6 | N23: =$N$17*Parameters!E20 -> 8.1103582e+08 | V23: 0.090905111 | W23: =(V23*$U$17)/(Parameters!B20*POWER(Parameters!$B$8, $C$17)) -> 0.13719183 | X23: =$U$17*V23 -> 3.0358475e+09 | Y23: =Parameters!D20 -> 0.053698687 | Z23: =(Y23*$U$17)/(Parameters!B20*POWER(Parameters!$B$8, $C$17)) -> 0.081040779 | AA23: =$U$17*Y23 -> 1.7933098e+09 | AD23: =Parameters!B20*POWER(Parameters!$B$8, $C$17) -> 2.2128486e+10 | AF23: =AD23+AE23-X23 -> 1.9092639e+10 | AG23: =AD23+AE23-AA23 -> 2.0335177e+10 | AH23: =($AB$17+$I$17)/10 -> 337517.81 | AI23: =AF23/AH23 -> 56567.797 | AK23: =AG23/AH23 -> 60249.196 | AM23: =(POWER(AI23, -0.26) - 1)/-0.26 -> 3.6226121 | AN23: =(AM23-$AM$18)*100 -> 18.731269 | AO23: =LOG(AI23) -> 4.7525693 | AP23: =(POWER(AK23, -0.26) - 1)/-0.26 -> 3.6262467 | AQ23: =(AP23-$AP$18)*100 -> 18.421523 | AR23: =LOG(AK23) -> 4.7799513 | AT23: 1.9033161 | AX23: =SQRT(AO23) -> 2.1800388 | BB23: 1.9042706 | BF23: =SQRT(AR23) -> 2.18631
A24: 7 | N24: =$N$17*Parameters!E21 -> 6.4882865e+08 | V24: 0.11035602 | W24: =(V24*$U$17)/(Parameters!B21*POWER(Parameters!$B$8, $C$17)) -> 0.142273 | X24: =$U$17*V24 -> 3.685426e+09 | Y24: =Parameters!D21 -> 0.083813868 | Z24: =(Y24*$U$17)/(Parameters!B21*POWER(Parameters!$B$8, $C$17)) -> 0.10805437 | AA24: =$U$17*Y24 -> 2.7990298e+09 | AD24: =Parameters!B21*POWER(Parameters!$B$8, $C$17) -> 2.5903902e+10 | AF24: =AD24+AE24-X24 -> 2.2218476e+10 | AG24: =AD24+AE24-AA24 -> 2.3104872e+10 | AH24: =($AB$17+$I$17)/10 -> 337517.81 | AI24: =AF24/AH24 -> 65829.047 | AK24: =AG24/AH24 -> 68455.268 | AM24: =(POWER(AI24, -0.26) - 1)/-0.26 -> 3.631253 | AN24: =(AM24-$AM$18)*100 -> 19.595361 | AO24: =LOG(AI24) -> 4.8184176 | AP24: =(POWER(AK24, -0.26) - 1)/-0.26 -> 3.6334277 | AQ24: =(AP24-$AP$18)*100 -> 19.139623 | AR24: =LOG(AK24) -> 4.8354069 | AT24: 1.9055847 | AX24: =SQRT(AO24) -> 2.1950894 | BB24: 1.9061552 | BF24: =SQRT(AR24) -> 2.1989559
A25: 8 | N25: =$N$17*Parameters!E22 -> 4.8662149e+08 | V25: 0.13623162 | W25: =(V25*$U$17)/(Parameters!B22*POWER(Parameters!$B$8, $C$17)) -> 0.14735418 | X25: =$U$17*V25 -> 4.5495616e+09 | Y25: =Parameters!D22 -> 0.13736006 | Z25: =(Y25*$U$17)/(Parameters!B22*POWER(Parameters!$B$8, $C$17)) -> 0.14857476 | AA25: =$U$17*Y25 -> 4.587247e+09 | AD25: =Parameters!B22*POWER(Parameters!$B$8, $C$17) -> 3.0875008e+10 | AF25: =AD25+AE25-X25 -> 2.6325447e+10 | AG25: =AD25+AE25-AA25 -> 2.6287761e+10 | AH25: =($AB$17+$I$17)/10 -> 337517.81 | AI25: =AF25/AH25 -> 77997.208 | AK25: =AG25/AH25 -> 77885.553 | AM25: =(POWER(AI25, -0.26) - 1)/-0.26 -> 3.640524 | AN25: =(AM25-$AM$18)*100 -> 20.522461 | AO25: =LOG(AI25) -> 4.8920791 | AP25: =(POWER(AK25, -0.26) - 1)/-0.26 -> 3.6404474 | AQ25: =(AP25-$AP$18)*100 -> 19.841595 | AR25: =LOG(AK25) -> 4.8914569 | AT25: 1.9080157 | AX25: =SQRT(AO25) -> 2.2118045 | BB25: 1.9079957 | BF25: =SQRT(AR25) -> 2.2116638
A26: 9 | N26: =$N$17*Parameters!E23 -> 3.2441433e+08 | V26: 0.17539672 | W26: =(V26*$U$17)/(Parameters!B23*POWER(Parameters!$B$8, $C$17)) -> 0.15243536 | X26: =$U$17*V26 -> 5.8575111e+09 | Y26: =Parameters!D23 -> 0.21757858 | Z26: =(Y26*$U$17)/(Parameters!B23*POWER(Parameters!$B$8, $C$17)) -> 0.18909515 | AA26: =$U$17*Y26 -> 7.2662073e+09 | AD26: =Parameters!B23*POWER(Parameters!$B$8, $C$17) -> 3.8426196e+10 | AF26: =AD26+AE26-X26 -> 3.2568685e+10 | AG26: =AD26+AE26-AA26 -> 3.1159989e+10 | AH26: =($AB$17+$I$17)/10 -> 337517.81 | AI26: =AF26/AH26 -> 96494.715 | AK26: =AG26/AH26 -> 92321.021 | AM26: =(POWER(AI26, -0.26) - 1)/-0.26 -> 3.6515929 | AN26: =(AM26-$AM$18)*100 -> 21.629346 | AO26: =LOG(AI26) -> 4.9845035 | AP26: =(POWER(AK26, -0.26) - 1)/-0.26 -> 3.6493432 | AQ26: =(AP26-$AP$18)*100 -> 20.731176 | AR26: =LOG(AK26) -> 4.9653006 | AT26: 1.9109141 | AX26: =SQRT(AO26) -> 2.2326002 | BB26: 1.9103254 | BF26: =SQRT(AR26) -> 2.2282954
A27: 10 | N27: =$N$17*Parameters!E24 -> 1.6220716e+08 | V27: 0.3154254 | W27: =(V27*$U$17)/(Parameters!B24*POWER(Parameters!$B$8, $C$17)) -> 0.15751654 | X27: =$U$17*V27 -> 1.0533879e+10 | Y27: =Parameters!D24 -> 0.43275574 | Z27: =(Y27*$U$17)/(Parameters!B24*POWER(Parameters!$B$8, $C$17)) -> 0.21610874 | AA27: =$U$17*Y27 -> 1.4452217e+10 | AD27: =Parameters!B24*POWER(Parameters!$B$8, $C$17) -> 6.6874746e+10 | AF27: =AD27+AE27-X27 -> 5.6340867e+10 | AG27: =AD27+AE27-AA27 -> 5.2422529e+10 | AH27: =($AB$17+$I$17)/10 -> 337517.81 | AI27: =AF27/AH27 -> 166927.09 | AK27: =AG27/AH27 -> 155317.81 | AM27: =(POWER(AI27, -0.26) - 1)/-0.26 -> 3.6774326 | AN27: =(AM27-$AM$18)*100 -> 24.213323 | AO27: =LOG(AI27) -> 5.2225268 | AP27: =(POWER(AK27, -0.26) - 1)/-0.26 -> 3.6742407 | AQ27: =(AP27-$AP$18)*100 -> 23.220921 | AR27: =LOG(AK27) -> 5.1912213 | AT27: 1.9176633 | AX27: =SQRT(AO27) -> 2.2852848 | BB27: 1.9168309 | BF27: =SQRT(AR27) -> 2.2784252
A29: Decile | B29: Year | D29: NZS income per recipient | V29: Baseline Tax | Y29: Progressive Tax | AB29: Size tax paying group by income group | AD29: Gross income | AF29: Net Income Baseline | AG29: Net income Progressive | AH29: Quintile size | AI29: Average income pp baseline | AK29: Average income pp progressive | AM29: Utility score baseline | AP29: Utility score progressive | AS29: Social welfare function basline tax isoelastic utility | AW29: SWF baseline tax log utility | BA29: SWF progressive tax isoelastic utility | BE29: SWF progressive tax log utility
B30: Year | C30: Years since base | D30: Base year annual rate singles | E30: Base year annual rate couples | F30: Mulitplier | G30: Current year real rate singles | H30: Current year annual rate couples | I30: 65+ employed population current year | J30: Single | K30: In a relationship | L30: NZS paid singles rate | M30: NZS paid couples rate | N30: NZS paid total to employed 65+ | O30: Total 65+ population | P30: Single | Q30: In a relationship | R30: NZS paid singles rate | S30: NZS paid couples rate | T30: NZS paid total to 65+ | U30: NZS paid total after means test | V30: Revenue share | W30: Implied average tax rate | X30: Decile NZS cost | Y30: Revenue share | Z30: Implied average tax rate | AA30: Decile NZS cost | AB30: Employed working age pop current year | AC30: Total tax paying population | AD30: Employment income | AE30: Pension income | AF30: Total income | AG30: Total income | AM30: Isoelastic p=1.26 | AN30: Isoelastic normalised | AO30: Isoelsatic p = 1 | AP30: Isoelastic p=1.26 | AQ30: Isoelastic normalised | AR30: Isoelsatic p = 1 | AS30: Utilitarian | AT30: Adjusted score | AU30: Prioritarian | AV30: Maximin | AW30: Utilitarian | AX30: Adjusted score | AY30: Prioritarian | AZ30: Maximin | BA30: Utilitarian | BB30: Adjusted score | BC30: Prioritarian | BD30: Maximin | BE30: Utilitarian | BF30: Adjusted score | BG30: Prioritarian | BH30: Maximin
A31: Overall | B31: 2078 | C31: 54 | D31: =Parameters!$B$4 -> 27012.44 | E31: =Parameters!$B$5 -> 20778.68 | F31: =Parameters!$B$8 -> 1.01088 | G31: =D31*POWER(F31,C31) -> 48455.429 | H31: =E31*POWER(F31,C31) -> 37273.192 | I31: =Parameters!$B$3*Parameters!B42 -> 557660.4 | J31: =I31*Parameters!$B$10 -> 234217.37 | K31: =I31*Parameters!$B$9 -> 323443.03 | L31: =J31*G31 -> 1.1349103e+10 | M31: =K31*H31 -> 1.2055754e+10 | N31: =M31+L31 -> 2.3404857e+10 | O31: =Parameters!B42 -> 2239600 | P31: =O31*Parameters!$B$10 -> 940632 | Q31: =O31*Parameters!$B$9 -> 1298968 | R31: =P31*G31 -> 4.5578727e+10 | S31: =Q31*H31 -> 4.8416683e+10 | T31: =S31+R31 -> 9.399541e+10 | U31: =T31-SUM(N37:N41) -> 8.7612268e+10 | AA31: =SUM(AA32:AA41) -> 8.7612268e+10 | AB31: =Parameters!C42*Parameters!B2 -> 3564796.4 | AC31: =AB31+I31 -> 4122456.8 | AD31: =SUM(AD32:AD41) -> 3.4871304e+11 | AE31: =N31 -> 2.3404857e+10 | AF31: =AD31+AE31-X31 -> 3.721179e+11 | AG31: =AD31+AE31-AA31 -> 2.8450563e+11 | AS31: =SUM(AN32:AN41) -> 179.87872 | AT31: Prioriatian | AU31: =SUM(AT32:AT41) -> 19.013252 | AV31: =MIN(AM33:AM41) -> 3.5603096 | AW31: =SUM(AO32:AO41) -> 47.27866 | AX31: Prioritarian | AY31: =SUM(AX32:AX41) -> 21.731569 | AZ31: =MIN(AO33:AO41) -> 4.3419123 | BA31: =SUM(AQ32:AQ41) -> 176.44567 | BB31: Prioriatian | BC31: =SUM(BB32:BB41) -> 19.021975 | BD31: =MIN(AP33:AP41) -> 3.5676754 | BE31: =SUM(AR32:AR41) -> 47.478881 | BF31: Prioriatian | BG31: =SUM(BF31:BF41) -> 21.779335 | BH31: =MIN(AR33:AR41) -> 4.3855193
A32: 1 | N32: =$N$31*Parameters!E15 -> 4.2554286e+09 | V32: =Parameters!C15 -> 0.0036096394 | W32: =(V32*$U$31)/(Parameters!B15*POWER(Parameters!$B$8,$C$31)) -> 0.22089852 | X32: =$U$31*V32 -> 3.1624869e+08 | Y32: =Parameters!D15 -> 0 | Z32: =(Y32*$U$31)/(Parameters!B15*POWER(Parameters!$B$8,$C$31)) -> 0 | AA32: =$U$31*Y32 -> 0 | AD32: =Parameters!B15*POWER(Parameters!$B$8,$C$31) -> 1.431647e+09 | AE32: =$AE$31*Parameters!E15 -> 4.2554286e+09 | AF32: =AD32+AE32-X32 -> 5.3708269e+09 | AG32: =AD32+AE32-AA32 -> 5.6870756e+09 | AH32: =($AB$31+$I$31)/10 -> 412245.68 | AI32: =AF32/AH32 -> 13028.219 | AK32: =AG32/AH32 -> 13795.355 | AM32: =(POWER(AI32, -0.26) - 1)/-0.26 -> 3.5186951 | AN32: =(AM32-$AM$18)*100 -> 8.3395727 | AO32: =LOG(AI32) -> 4.114885 | AP32: =(POWER(AK32, -0.26) - 1)/-0.26 -> 3.5235303 | AQ32: =(AP32-$AP$18)*100 -> 8.1498793 | AR32: =LOG(AK32) -> 4.1397329 | AT32: {=SQRT(AM32:AM41)} -> 1.8758185 | AX32: =SQRT(AO32) -> 2.0285179 | BB32: {=SQRT(AP32:AP41)} -> 1.8771069 | BF32: =SQRT(AR32) -> 2.0346334
A33: 2 | N33: =$N$31*Parameters!E16 -> 3.8298857e+09 | V33: =Parameters!C16 -> 0.014401036 | W33: =(V33*$U$31)/(Parameters!B16*POWER(Parameters!$B$8,$C$31)) -> 0.19439069 | X33: =$U$31*V33 -> 1.2617075e+09 | Y33: =Parameters!D16 -> 0.0034800777 | Z33: =(Y33*$U$31)/(Parameters!B16*POWER(Parameters!$B$8,$C$31)) -> 0.04697542 | AA33: =$U$31*Y33 -> 3.048975e+08 | AD33: =Parameters!B16*POWER(Parameters!$B$8,$C$31) -> 6.4905754e+09 | AE33: =$AE$31*Parameters!E16 -> 3.8298857e+09 | AF33: =AD33+AE33-X33 -> 9.0587537e+09 | AG33: =AD33+AE33-AA33 -> 1.0015564e+10 | AH33: =($AB$31+$I$31)/10 -> 412245.68 | AI33: =AF33/AH33 -> 21974.163 | AK33: =AG33/AH33 -> 24295.133 | AM33: =(POWER(AI33, -0.26) - 1)/-0.26 -> 3.5603096 | AN33: =(AM33-$AM$18)*100 -> 12.501019 | AO33: =LOG(AI33) -> 4.3419123 | AP33: =(POWER(AK33, -0.26) - 1)/-0.26 -> 3.5676754 | AQ33: =(AP33-$AP$18)*100 -> 12.564389 | AR33: =LOG(AK33) -> 4.3855193 | AT33: 1.8868783 | AX33: =SQRT(AO33) -> 2.0837256 | BB33: 1.8888291 | BF33: =SQRT(AR33) -> 2.0941631
A34: 3 | N34: =$N$31*Parameters!E17 -> 3.4043429e+09 | V34: =Parameters!C17 -> 0.031399077 | W34: =(V34*$U$31)/(Parameters!B17*POWER(Parameters!$B$8,$C$31)) -> 0.20322663 | X34: =$U$31*V34 -> 2.7509444e+09 | Y34: =Parameters!D17 -> 0.010886748 | Z34: =(Y34*$U$31)/(Parameters!B17*POWER(Parameters!$B$8,$C$31)) -> 0.070463129 | AA34: =$U$31*Y34 -> 9.5381272e+08 | AD34: =Parameters!B17*POWER(Parameters!$B$8,$C$31) -> 1.3536338e+10 | AE34: =$AE$31*Parameters!E17 -> 3.4043429e+09 | AF34: =AD34+AE34-X34 -> 1.4189736e+10 | AG34: =AD34+AE34-AA34 -> 1.5986868e+10 | AH34: =($AB$31+$I$31)/10 -> 412245.68 | AI34: =AF34/AH34 -> 34420.582 | AK34: =AG34/AH34 -> 38779.953 | AM34: =(POWER(AI34, -0.26) - 1)/-0.26 -> 3.5917909 | AN34: =(AM34-$AM$18)*100 -> 15.649145 | AO34: =LOG(AI34) -> 4.5368182 | AP34: =(POWER(AK34, -0.26) - 1)/-0.26 -> 3.5995563 | AQ34: =(AP34-$AP$18)*100 -> 15.752482 | AR34: =LOG(AK34) -> 4.5886073 | AT34: 1.8952021 | AX34: =SQRT(AO34) -> 2.1299808 | BB34: 1.8972497 | BF34: =SQRT(AR34) -> 2.1421035
A35: 4 | N35: =$N$31*Parameters!E18 -> 2.9788e+09 | V35: =Parameters!C18 -> 0.051692243 | W35: =(V35*$U$31)/(Parameters!B18*POWER(Parameters!$B$8,$C$31)) -> 0.21206257 | X35: =$U$31*V35 -> 4.5288746e+09 | Y35: =Parameters!D18 -> 0.022901399 | Z35: =(Y35*$U$31)/(Parameters!B18*POWER(Parameters!$B$8,$C$31)) -> 0.093950839 | AA35: =$U$31*Y35 -> 2.0064435e+09 | AD35: =Parameters!B18*POWER(Parameters!$B$8,$C$31) -> 2.1356313e+10 | AE35: =$AE$31*Parameters!E18 -> 2.9788e+09 | AF35: =AD35+AE35-X35 -> 1.9806238e+10 | AG35: =AD35+AE35-AA35 -> 2.2328669e+10 | AH35: =($AB$31+$I$31)/10 -> 412245.68 | AI35: =AF35/AH35 -> 48044.743 | AK35: =AG35/AH35 -> 54163.5 | AM35: =(POWER(AI35, -0.26) - 1)/-0.26 -> 3.6129162 | AN35: =(AM35-$AM$18)*100 -> 17.761675 | AO35: =LOG(AI35) -> 4.6816459 | AP35: =(POWER(AK35, -0.26) - 1)/-0.26 -> 3.6200735 | AQ35: =(AP35-$AP$18)*100 -> 17.804197 | AR35: =LOG(AK35) -> 4.7337067 | AT35: 1.9007673 | AX35: =SQRT(AO35) -> 2.1637111 | BB35: 1.9026491 | BF35: =SQRT(AR35) -> 2.1757083
A36: 5 | N36: =$N$31*Parameters!E19 -> 2.5532571e+09 | V36: =Parameters!C19 -> 0.070583126 | W36: =(V36*$U$31)/(Parameters!B19*POWER(Parameters!$B$8,$C$31)) -> 0.22089852 | X36: =$U$31*V36 -> 6.1839477e+09 | Y36: =Parameters!D19 -> 0.037524833 | Z36: =(Y36*$U$31)/(Parameters!B19*POWER(Parameters!$B$8,$C$31)) -> 0.11743855 | AA36: =$U$31*Y36 -> 3.2876357e+09 | AD36: =Parameters!B19*POWER(Parameters!$B$8,$C$31) -> 2.7994519e+10 | AE36: =$AE$31*Parameters!E19 -> 2.5532571e+09 | AF36: =AD36+AE36-X36 -> 2.4363829e+10 | AG36: =AD36+AE36-AA36 -> 2.7260141e+10 | AH36: =($AB$31+$I$31)/10 -> 412245.68 | AI36: =AF36/AH36 -> 59100.264 | AK36: =AG36/AH36 -> 66125.958 | AM36: =(POWER(AI36, -0.26) - 1)/-0.26 -> 3.6251431 | AN36: =(AM36-$AM$18)*100 -> 18.984368 | AO36: =LOG(AI36) -> 4.7715894 | AP36: =(POWER(AK36, -0.26) - 1)/-0.26 -> 3.6315043 | AQ36: =(AP36-$AP$18)*100 -> 18.947284 | AR36: =LOG(AK36) -> 4.820372 | AT36: 1.9039809 | AX36: =SQRT(AO36) -> 2.1843968 | BB36: 1.9056506 | BF36: =SQRT(AR36) -> 2.1955346
A37: 6 | N37: =$N$31*Parameters!E20 -> 2.1277143e+09 | V37: =Parameters!C20 -> 0.090905111 | W37: =(V37*$U$31)/(Parameters!B20*POWER(Parameters!$B$8,$C$31)) -> 0.2385704 | X37: =$U$31*V37 -> 7.9644029e+09 | Y37: =Parameters!D20 -> 0.053698687 | Z37: =(Y37*$U$31)/(Parameters!B20*POWER(Parameters!$B$8,$C$31)) -> 0.14092626 | AA37: =$U$31*Y37 -> 4.7046638e+09 | AD37: =Parameters!B20*POWER(Parameters!$B$8,$C$31) -> 3.3383869e+10 | AF37: =AD37+AE37-X37 -> 2.5419466e+10 | AG37: =AD37+AE37-AA37 -> 2.8679205e+10 | AH37: =($AB$31+$I$31)/10 -> 412245.68 | AI37: =AF37/AH37 -> 61660.965 | AK37: =AG37/AH37 -> 69568.237 | AM37: =(POWER(AI37, -0.26) - 1)/-0.26 -> 3.627567 | AN37: =(AM37-$AM$18)*100 -> 19.226761 | AO37: =LOG(AI37) -> 4.7900103 | AP37: =(POWER(AK37, -0.26) - 1)/-0.26 -> 3.6343178 | AQ37: =(AP37-$AP$18)*100 -> 19.228636 | AR37: =LOG(AK37) -> 4.842411 | AT37: 1.9046173 | AX37: =SQRT(AO37) -> 2.1886092 | BB37: 1.9063887 | BF37: =SQRT(AR37) -> 2.2005479
A38: 7 | N38: =$N$31*Parameters!E21 -> 1.7021714e+09 | V38: =Parameters!C21 -> 0.11035602 | W38: =(V38*$U$31)/(Parameters!B21*POWER(Parameters!$B$8,$C$31)) -> 0.24740634 | X38: =$U$31*V38 -> 9.6685415e+09 | Y38: =Parameters!D21 -> 0.083813868 | Z38: =(Y38*$U$31)/(Parameters!B21*POWER(Parameters!$B$8,$C$31)) -> 0.18790168 | AA38: =$U$31*Y38 -> 7.343123e+09 | AD38: =Parameters!B21*POWER(Parameters!$B$8,$C$31) -> 3.9079603e+10 | AF38: =AD38+AE38-X38 -> 2.9411062e+10 | AG38: =AD38+AE38-AA38 -> 3.173648e+10 | AH38: =($AB$31+$I$31)/10 -> 412245.68 | AI38: =AF38/AH38 -> 71343.53 | AK38: =AG38/AH38 -> 76984.385 | AM38: =(POWER(AI38, -0.26) - 1)/-0.26 -> 3.6357012 | AN38: =(AM38-$AM$18)*100 -> 20.040175 | AO38: =LOG(AI38) -> 4.8533546 | AP38: =(POWER(AK38, -0.26) - 1)/-0.26 -> 3.639824 | AQ38: =(AP38-$AP$18)*100 -> 19.779257 | AR38: =LOG(AK38) -> 4.8864026 | AT38: 1.9067515 | AX38: =SQRT(AO38) -> 2.203033 | BB38: 1.9078323 | BF38: =SQRT(AR38) -> 2.2105209
A39: 8 | N39: =$N$31*Parameters!E22 -> 1.2766286e+09 | V39: =Parameters!C22 -> 0.13623162 | W39: =(V39*$U$31)/(Parameters!B22*POWER(Parameters!$B$8,$C$31)) -> 0.25624228 | X39: =$U$31*V39 -> 1.1935561e+10 | Y39: =Parameters!D22 -> 0.13736006 | Z39: =(Y39*$U$31)/(Parameters!B22*POWER(Parameters!$B$8,$C$31)) -> 0.25836481 | AA39: =$U$31*Y39 -> 1.2034427e+10 | AD39: =Parameters!B22*POWER(Parameters!$B$8,$C$31) -> 4.6579202e+10 | AF39: =AD39+AE39-X39 -> 3.4643641e+10 | AG39: =AD39+AE39-AA39 -> 3.4544775e+10 | AH39: =($AB$31+$I$31)/10 -> 412245.68 | AI39: =AF39/AH39 -> 84036.396 | AK39: =AG39/AH39 -> 83796.574 | AM39: =(POWER(AI39, -0.26) - 1)/-0.26 -> 3.6444728 | AN39: =(AM39-$AM$18)*100 -> 20.917337 | AO39: =LOG(AI39) -> 4.9244674 | AP39: =(POWER(AK39, -0.26) - 1)/-0.26 -> 3.6443229 | AQ39: =(AP39-$AP$18)*100 -> 20.229139 | AR39: =LOG(AK39) -> 4.9232263 | AT39: 1.9090502 | AX39: =SQRT(AO39) -> 2.2191141 | BB39: 1.909011 | BF39: =SQRT(AR39) -> 2.2188344
A40: 9 | N40: =$N$31*Parameters!E23 -> 8.5108572e+08 | V40: =Parameters!C23 -> 0.17539672 | W40: =(V40*$U$31)/(Parameters!B23*POWER(Parameters!$B$8,$C$31)) -> 0.26507822 | X40: =$U$31*V40 -> 1.5366905e+10 | Y40: =Parameters!D23 -> 0.21757858 | Z40: =(Y40*$U$31)/(Parameters!B23*POWER(Parameters!$B$8,$C$31)) -> 0.32882794 | AA40: =$U$31*Y40 -> 1.9062553e+10 | AD40: =Parameters!B23*POWER(Parameters!$B$8,$C$31) -> 5.7971209e+10 | AF40: =AD40+AE40-X40 -> 4.2604304e+10 | AG40: =AD40+AE40-AA40 -> 3.8908656e+10 | AH40: =($AB$31+$I$31)/10 -> 412245.68 | AI40: =AF40/AH40 -> 103346.88 | AK40: =AG40/AH40 -> 94382.203 | AM40: =(POWER(AI40, -0.26) - 1)/-0.26 -> 3.6550324 | AN40: =(AM40-$AM$18)*100 -> 21.973302 | AO40: =LOG(AI40) -> 5.0142974 | AP40: =(POWER(AK40, -0.26) - 1)/-0.26 -> 3.6504699 | AQ40: =(AP40-$AP$18)*100 -> 20.843841 | AR40: =LOG(AK40) -> 4.9748901 | AT40: 1.9118139 | AX40: =SQRT(AO40) -> 2.2392627 | BB40: 1.9106203 | BF40: =SQRT(AR40) -> 2.2304462
